Workbook
Name AUD: FX!$C$5
Name CHF: FX!$C$3
Name CNY: FX!$C$11
Name DKK: FX!$C$2
Name DKKUSD: #REF!
Name EUR: FX!$C$4
Name GBP: FX!$C$6
Name HKD: FX!$C$8
Name INR: FX!$C$10
Name JPY: FX!$C$7
Name KRW: FX!$C$9

Sheet Main
D2: =RANDBETWEEN(1,D257) -> 169 | H2: =SUM(H5:H419)-H10-H8-H13-H19-H23-H26-H52-H57 -> 4704489.9 | M2: =MIN(M5:M87) -> 45535 | O2: =AVERAGE(O5:O25) -> 0.069210709 | S2: EV/EPS | Y2: EPS
B3: R | C3: C | E3: Name | F3: Ticker | G3: Price | H3: MC | I3: NC | J3: EV | K3: Update | L3: SO | M3: Last | N3: NPV | O3: Upside | P3: ROIC | Q3: Terminal | R3: Discount | S3: 2022 | T3: 2023 | U3: 2024 | V3: 2025 | W3: 2026 | X3: 2027 | Y3: 2022 | Z3: 2023 | AA3: 2024 | AB3: 2025 | AC3: 2026 | AD3: 2027 | AE3: Founded | AF3: Location
S4: =TRIMMEAN(S5:S301,10%) -> 39.229343 | T4: =TRIMMEAN(T5:T301,10%) -> 85.398914 | U4: =TRIMMEAN(U5:U301,10%) -> 50.025711 | V4: =TRIMMEAN(V5:V301,10%) -> 17.311967 | W4: =TRIMMEAN(W5:W301,10%) -> 15.537076 | X4: =TRIMMEAN(X5:X301,10%) -> 14.509885 | Y4: - | Z4: - | AA4: - | AB4: - | AC4: - | AD4: - | AE4: =AVERAGE(AE5:AE222) -> 1969.4722
A5: x | D5: 1 | E5: Eli Lilly | F5: LLY | G5: 707 | H5: =+G5*L5 -> 636724.2 | I5: =+[1]Main!$J$5-[1]Main!$J$6 -> -32073 | J5: =H5-I5 -> 668797.2 | K5: Q125 | L5: =+[1]Main!$J$3 -> 900.6 | M5: 45873 | N5: =[1]Model!$FY$101 -> 929.05463 | O5: =+N5/G5-1 -> 0.31408011 | P5: =[1]Model!$FY$97 -> 0.02 | Q5: =[1]Model!$FY$98 -> 0 | R5: =[1]Model!$FY$99 -> 0.07 | S5: =($J5/$L5)/Y5 -> 107.62506 | T5: =($J5/$L5)/Z5 -> 128.03671 | U5: =($J5/$L5)/AA5 -> 63.416988 | V5: =($J5/$L5)/AB5 -> 34.064813 | W5: =($J5/$L5)/AC5 -> 25.037523 | X5: - | Y5: 6.9 | Z5: 5.8 | AA5: 11.71 | AB5: 21.8 | AC5: 29.66 | AD5: - | AE5: 1876
A6: x | D6: 2 | E6: J&J | F6: JNJ | G6: 176.12 | H6: =+G6*L6 -> 423744.72 | I6: =+[2]Main!$L$5-[2]Main!$L$6 -> -13471 | J6: =H6-I6 -> 437215.72 | K6: Q125 | L6: =+[2]Main!$L$3 -> 2406 | M6: 45875 | N6: =[2]Model!$FN$86 -> 0 | O6: =N6/G6-1 -> -1 | P6: =[2]Model!$FN$78 -> 2552.9 | Q6: =[2]Model!$FN$79 -> 0 | R6: =[2]Model!$FN$80 -> 0 | S6: =($J6/$L6)/Y6 -> 27.001325 | T6: =($J6/$L6)/Z6 -> 32.860564 | U6: =($J6/$L6)/AA6 -> 31.38496 | V6: =($J6/$L6)/AB6 -> 17.127137 | W6: =($J6/$L6)/AC6 -> 16.371074 | X6: =($J6/$L6)/AD6 -> 15.889201 | Y6: 6.73 | Z6: 5.53 | AA6: 5.79 | AB6: 10.61 | AC6: 11.1 | AD6: =+[2]Model!$FB$77 -> 11.43663 | AE6: 1886
A7: x | D7: 3 | E7: AbbVie | F7: ABBV | G7: 203.44 | H7: =+G7*L7 -> 360495.68 | I7: =+[3]Main!$K$5-[3]Main!$K$6 -> -64426 | J7: =H7-I7 -> 424921.68 | K7: Q125 | L7: =+[3]Main!$K$3 -> 1772 | M7: 45789 | N7: =[3]Model!$DT$78 -> 229.98813 | O7: =+N7/G7-1 -> 0.13049613 | P7: =[3]Model!$DT$76 -> 0 | Q7: =[3]Model!$DT$75 -> -0.01 | R7: =[3]Model!$DT$74 -> 0.06 | S7: =($J7/$L7)/Y7 -> 36.168595 | T7: =($J7/$L7)/Z7 -> 88.160951 | U7: =($J7/$L7)/AA7 -> 100.3338 | V7: =($J7/$L7)/AB7 -> 19.607342 | W7: =($J7/$L7)/AC7 -> 17.140657 | X7: - | Y7: 6.63 | Z7: 2.72 | AA7: 2.39 | AB7: 12.23 | AC7: 13.99 | AD7: - | AE7: 1888
A8: x | D8: =+D7+1 -> 4 | E8: AstraZeneca | F8: AZN | G8: 74.66 | H8: =+G8*L8*2 -> 232939.2 | I8: =+[4]Main!$K$5-[4]Main!$K$6 -> -26067 | J8: =H8-I8 -> 259006.2 | K8: Q125 | L8: =+[4]Main!$K$3 -> 1560 | M8: 45820 | S8: =($J8/$L8)/Y8 -> 156.63171 | T8: =($J8/$L8)/Z8 -> 86.473758 | U8: =($J8/$L8)/AA8 -> 73.1408 | V8: =($J8/$L8)/AB8 -> 36.813662 | W8: =($J8/$L8)/AC8 -> 32.618785 | X8: - | Y8: 1.06 | Z8: 1.92 | AA8: 2.27 | AB8: 4.51 | AC8: 5.09 | AD8: -
A9: x | D9: =+D8 -> 4 | E9: AstraZeneca | F9: AZN LN | G9: 11136 | H9: =+G9*L9/100*GBP -> 225838.08 | I9: =+[4]Main!$K$5-[4]Main!$K$6 -> -26067 | J9: =H9-I9 -> 251905.08 | K9: =+K8 -> Q125 | L9: =+[4]Main!$K$3 -> 1560 | M9: =+M8 -> 45820 | N9: - | O9: - | P9: - | Q9: - | R9: - | S9: - | T9: - | U9: - | V9: - | W9: - | X9: - | Y9: - | Z9: - | AA9: - | AB9: - | AC9: - | AD9: -
A10: x | D10: =+D9+1 -> 5 | E10: Novo Nordisk | F10: NVO | G10: 47.39 | H10: =+L10*G10 -> 210695.94 | I10: =([5]Main!$J$5-[5]Main!$J$6)/DKK -> -10378.206 | J10: =H10-I10 -> 221074.15 | K10: Q324 | L10: =+[5]Main!$J$3 -> 4446 | M10: 45671 | N10: - | O10: - | P10: - | Q10: - | R10: - | S10: =($J10/$L10)/Y10 -> 28.742358 | T10: =($J10/$L10)/Z10 -> 18.348443 | U10: =($J10/$L10)/AA10 -> 15.113763 | V10: =($J10/$L10)/AB10 -> 12.493538 | W10: =($J10/$L10)/AC10 -> 10.534805 | X10: - | Y10: 1.73 | Z10: 2.71 | AA10: 3.29 | AB10: 3.98 | AC10: 4.72 | AD10: - | AE10: 1923
A11: x | D11: =+D10 -> 5 | E11: Novo Nordisk | F11: NOVOB | G11: 313 | H11: =+G11*L11/DKK -> 197193.99 | I11: =([5]Main!$J$5-[5]Main!$J$6)/DKK -> -10378.206 | J11: =H11-I11 -> 207572.2 | K11: =+K10 -> Q324 | L11: =+[5]Main!$J$3 -> 4446 | M11: =+M10 -> 45671 | N11: =+[5]Model!$DM$53 -> 443.65753 | O11: =N11/G11-1 -> 0.41743621 | P11: =[5]Model!$DM$49*-1 -> 0.01 | Q11: =+[5]Model!$DM$50 -> -0.01 | R11: =+[5]Model!$DM$51 -> 0.08 | S11: - | T11: - | U11: - | V11: - | W11: - | X11: - | Y11: - | Z11: - | AA11: - | AB11: - | AC11: - | AD11: - | AE11: 1923
A12: x | D12: =+D11+1 -> 6 | E12: Roche | F12: ROG VX | G12: 268 | H12: =+L12*G12 -> 214508 | I12: =+[6]Main!$J$5-[6]Main!$J$6 -> -17337 | J12: =H12-I12 -> 231845 | K12: Q423 | L12: =+[6]Main!$J$3 -> 800.403 | M12: 45754 | S12: - | T12: - | U12: =($J12/$L12)/AA12 -> 15.665784 | V12: =($J12/$L12)/AB12 -> 14.475779 | W12: =($J12/$L12)/AC12 -> 13.599077 | X12: =($J12/$L12)/AD12 -> 13.130568 | Y12: - | Z12: - | AA12: 18.49 | AB12: 20.01 | AC12: 21.3 | AD12: 22.06 | AE12: 1896
A13: x | D13: =+D12+1 -> 7 | E13: Novartis | F13: NVS | G13: 117.92 | H13: =+G13*L13 -> 231035.22 | I13: =+[7]Main!$K$6-[7]Main!$K$7 -> -22271 | J13: =H13-I13 -> 253306.22 | K13: Q125 | L13: =+[7]Main!$K$4 -> 1959.2539 | M13: 45793 | S13: =($J13/$L13)/Y13 -> 40.528866 | T13: =($J13/$L13)/Z13 -> 18.082109 | U13: =($J13/$L13)/AA13 -> 21.839034 | V13: =($J13/$L13)/AB13 -> 14.929224 | W13: =($J13/$L13)/AC13 -> 14.349288 | X13: - | Y13: 3.19 | Z13: 7.15 | AA13: 5.92 | AB13: 8.66 | AC13: 9.01 | AD13: -
A14: x | D14: =+D13 -> 7 | E14: Novartis | F14: NOVN VX | G14: 94.58 | H14: =+G14*L14/CHF -> 203633.22 | I14: =+[7]Main!$K$6-[7]Main!$K$7 -> -22271 | J14: =H14-I14 -> 225904.22 | K14: Q125 | L14: =+[7]Main!$K$4 -> 1959.2539 | M14: =+M13 -> 45793 | N14: - | O14: - | P14: - | Q14: - | R14: - | S14: - | T14: - | U14: - | V14: - | W14: - | X14: - | Y14: - | Z14: - | AA14: - | AB14: - | AC14: - | AD14: -
A15: x | D15: =+D14+1 -> 8 | E15: Merck | F15: MRK | G15: 85 | H15: =+G15*L15 -> 215135 | I15: =+[8]Main!$J$5-[8]Main!$J$6 -> -26006 | J15: =H15-I15 -> 241141 | K15: Q424 | L15: =+[8]Main!$J$3 -> 2531 | M15: 45771 | N15: =[8]Model!$EM$113 -> 91.467148 | O15: =N15/G15-1 -> 0.076084093 | P15: =[8]Model!$EM$109 -> 0.01 | Q15: =[8]Model!$EM$110 -> -0.01 | R15: =[8]Model!$EM$111 -> 0.07 | S15: =($J15/$L15)/Y15 -> 16.685637 | T15: =($J15/$L15)/Z15 -> 680.53564 | U15: =($J15/$L15)/AA15 -> 14.135755 | V15: =($J15/$L15)/AB15 -> 10.705055 | W15: =($J15/$L15)/AC15 -> 9.8019537 | X15: - | Y15: 5.71 | Z15: 0.14 | AA15: 6.74 | AB15: 8.9 | AC15: 9.72 | AD15: - | AE15: 1919
A16: x | D16: =+D15+1 -> 9 | E16: Amgen | F16: AMGN | G16: 300 | H16: =+G16*L16 -> 162300 | I16: =[9]Main!$J$5-[9]Main!$J$6 -> -48571 | J16: =H16-I16 -> 210871 | K16: Q125 | L16: =[9]Main!$J$3 -> 541 | M16: 45804 | N16: =+[9]Model!$EM$60 -> 296.41443 | O16: =N16/G16-1 -> -0.011951887 | P16: =+[9]Model!$EM$56 -> 0.01 | Q16: =+[9]Model!$EM$57 -> -0.02 | R16: =+[9]Model!$EM$58 -> 0.08 | S16: =($J16/$L16)/Y16 -> 32.186626 | T16: =($J16/$L16)/Z16 -> 31.207369 | U16: =($J16/$L16)/AA16 -> 51.558206 | V16: =($J16/$L16)/AB16 -> 18.694486 | W16: =($J16/$L16)/AC16 -> 18.112455 | X16: - | Y16: 12.11 | Z16: 12.49 | AA16: 7.56 | AB16: 20.85 | AC16: 21.52 | AD16: - | AE16: 1980
A17: x | D17: =+D16+1 -> 10 | E17: Pfizer | F17: PFE | G17: 24.48 | H17: =+L17*G17 -> 139780.8 | I17: =+[10]Main!$K$5-[10]Main!$K$6 -> -42779 | J17: =H17-I17 -> 182559.8 | K17: Q125 | L17: =+[10]Main!$K$3 -> 5710 | M17: 45805 | S17: =($J17/$L17)/Y17 -> 5.8449623 | T17: =($J17/$L17)/Z17 -> 84.136695 | U17: =($J17/$L17)/AA17 -> 22.675138 | V17: =($J17/$L17)/AB17 -> 10.657315 | W17: =($J17/$L17)/AC17 -> 10.380501 | X17: - | Y17: 5.47 | Z17: 0.38 | AA17: 1.41 | AB17: 3 | AC17: 3.08 | AD17: -
A18: x | D18: =+D17+1 -> 11 | E18: Gilead | F18: GILD | G18: 113.75 | H18: =+G18*L18 -> 143211.25 | I18: =+[11]Main!$J$5-[11]Main!$J$6 -> -16720 | J18: =H18-I18 -> 159931.25 | K18: Q424 | L18: =+[11]Main!$J$3 -> 1259 | M18: 45768 | S18: =($J18/$L18)/Y18 -> 34.898456 | T18: =($J18/$L18)/Z18 -> 28.228974 | U18: =($J18/$L18)/AA18 -> 334.29048 | V18: =($J18/$L18)/AB18 -> 15.898671 | W18: =($J18/$L18)/AC18 -> 14.909669 | X18: - | Y18: 3.64 | Z18: 4.5 | AA18: 0.38 | AB18: 7.99 | AC18: 8.52 | AD18: -
A19: x | D19: =+D18+1 -> 12 | E19: Sanofi | F19: SAN | G19: 82 | H19: =G19*[12]Main!$K$3*EUR -> 113866.02 | I19: =([13]Main!$K$5-[13]Main!$K$6)*EUR -> -12746.13 | J19: =H19-I19 -> 126612.15 | K19: Q224 | L19: =+[12]Main!$K$3 -> 1251 | M19: 45776 | S19: - | T19: - | U19: - | V19: =($J19/$L19)/AB19 -> 22.097981 | W19: =($J19/$L19)/AC19 -> 20.121024 | X19: - | Y19: - | Z19: - | AA19: - | AB19: 4.58 | AC19: 5.03 | AD19: -
A20: x | D20: =+D19 -> 12 | E20: Sanofi | F20: SNY | G20: 47.76 | H20: =+G20*L20*2 -> 119495.52 | I20: =([13]Main!$K$5-[13]Main!$K$6)*EUR -> -12746.13 | J20: =H20-I20 -> 132241.65 | K20: =+K19 -> Q224 | L20: =+L19 -> 1251 | M20: =+M19 -> 45776 | N20: - | O20: - | P20: - | Q20: - | R20: - | S20: - | T20: - | U20: - | V20: - | W20: - | X20: - | Y20: - | Z20: - | AA20: - | AB20: - | AC20: - | AD20: -
A21: x | D21: =+D20+1 -> 13 | E21: Bristol-Myers | F21: BMY | G21: 45.38 | H21: =+G21*L21 -> 92076.02 | I21: =+[14]Main!$K$5-[14]Main!$K$6 -> -38470 | J21: =H21-I21 -> 130546.02 | K21: Q424 | L21: =+[14]Main!$K$3 -> 2029 | M21: 45771 | S21: =($J21/$L21)/Y21 -> 21.810196 | T21: =($J21/$L21)/Z21 -> 16.668414 | U21: =($J21/$L21)/AA21 -> -14.589587 | V21: =($J21/$L21)/AB21 -> 9.3790202 | W21: =($J21/$L21)/AC21 -> 10.599684 | X21: - | Y21: 2.95 | Z21: 3.86 | AA21: -4.41 | AB21: 6.86 | AC21: 6.07 | AD21: - | AE21: 1887
A22: x | D22: =+D21+1 -> 14 | E22: Vertex | F22: VRTX | G22: 401 | H22: =+G22*[15]Main!$M$3 -> 102975.67 | I22: =+[15]Main!$M$5-[15]Main!$M$6 -> 11358 | J22: =H22-I22 -> 91617.672 | K22: Q125 | L22: =+[15]Main!$M$3 -> 256.79719 | M22: 45789 | N22: =+[15]Model!$BK$34 -> 624.89046 | O22: =N22/G22-1 -> 0.55833032 | P22: =+[15]Model!$BK$32 -> 0.03 | Q22: =+[15]Model!$BK$30 -> -0.05 | R22: =[15]Model!$BK$30 -> -0.05 | S22: =($J22/$L22)/Y22 -> 27.829216 | T22: =($J22/$L22)/Z22 -> 25.685424 | U22: =($J22/$L22)/AA22 -> 30.132647 | V22: =($J22/$L22)/AB22 -> 19.831603 | W22: =($J22/$L22)/AC22 -> 17.144188 | X22: - | Y22: 12.82 | Z22: 13.89 | AA22: =-2.08+13.92 -> 11.84 | AB22: 17.99 | AC22: 20.81 | AD22: -
A23: x | D23: =+D22+1 -> 15 | E23: GSK | F23: GSK US | G23: 37.44 | H23: =+G23*L23/2 -> 77444.64 | I23: =([16]Main!$J$6-[16]Main!$J$7)*GBP -> -18131.1 | J23: =H23-I23 -> 95575.74 | K23: Q125 | L23: =+[16]Main!$J$4 -> 4137 | M23: 45805 | S23: =($J23/$L23)/Y23 -> 6.6964257 | T23: =($J23/$L23)/Z23 -> 5.9851473 | U23: =($J23/$L23)/AA23 -> 5.6763314 | V23: =($J23/$L23)/AB23 -> 5.1683822 | W23: =($J23/$L23)/AC23 -> 4.6766536 | X23: - | Y23: 3.45 | Z23: 3.86 | AA23: 4.07 | AB23: 4.47 | AC23: 4.94 | AD23: 5.35
A24: x | D24: =+D23 -> 15 | E24: GSK | F24: GSK LN | G24: 1398 | H24: =+G24*L24/100*GBP -> 75185.838 | I24: =([16]Main!$J$6-[16]Main!$J$7)*GBP -> -18131.1 | J24: =H24-I24 -> 93316.938 | K24: =+K23 -> Q125 | L24: =+L23 -> 4137 | M24: =+M23 -> 45805 | N24: - | O24: - | P24: - | Q24: - | R24: - | S24: =($J24/$L24)/Y24 -> 16.111906 | T24: =($J24/$L24)/Z24 -> 14.552689 | U24: =($J24/$L24)/AA24 -> 14.186584 | V24: =($J24/$L24)/AB24 -> 13.670708 | W24: =($J24/$L24)/AC24 -> 12.393774 | X24: - | Y24: 1.4 | Z24: 1.55 | AA24: 1.59 | AB24: 1.65 | AC24: 1.82 | AD24: 1.97
A25: x | D25: =+D24+1 -> 16 | E25: CSL | F25: CSL AU | G25: 264.91 | H25: =+G25*L25*AUD -> 86117.879 | I25: =[17]Main!$J$5-[17]Main!$J$6 -> -10363 | J25: =H25-I25 -> 96480.879 | K25: Q224 | L25: =+[17]Main!$J$3 -> 485.19931 | M25: 45822 | S25: =($J25/$L25)/Y25 -> 29.678796 | T25: =($J25/$L25)/Z25 -> 22.020812 | U25: =($J25/$L25)/AA25 -> 21.450694 | V25: =($J25/$L25)/AB25 -> 18.688716 | W25: =($J25/$L25)/AC25 -> 16.339189 | X25: - | Y25: 6.7 | Z25: 9.03 | AA25: 9.27 | AB25: 10.64 | AC25: 12.17 | AD25: 13.65
A26: x | D26: =+D25+1 -> 17 | E26: Takeda | F26: TAK | G26: 14.23 | H26: =+G26*2*L26 -> 44653.74 | I26: =([18]Main!$K$6-[18]Main!$K$7)/JPY -> -27370.052 | J26: =+H26-I26 -> 72023.792 | K26: Q224 | L26: =+[18]Main!$K$4 -> 1569 | M26: 45812
A27: x | D27: =+D26 -> 17 | E27: Takeda | F27: 4502 JP | G27: 4219 | H27: =+G27*L27/JPY -> 45573.914 | I27: =([18]Main!$K$6-[18]Main!$K$7)/JPY -> -27370.052 | J27: =+H27-I27 -> 72943.966 | K27: Q224 | L27: =+[18]Main!$K$4 -> 1569 | M27: =+M26 -> 45812
A28: x | D28: =+D27+1 -> 18 | E28: Chugai | F28: 4519 JP | G28: 7303 | H28: =+G28*L28/JPY -> 82728.416 | I28: =([19]Main!$J$5-[19]Main!$J$6)/JPY -> 5615.5456 | J28: =+H28-I28 -> 77112.87 | K28: Q224 | L28: =+[19]Main!$J$3 -> 1645.3926 | M28: 45537 | AE28: 1925
A29: x | D29: =+D28+1 -> 19 | E29: Merck KgAa | F29: MRK DE | G29: 108.45 | H29: =+G29*L29 -> 47175.75 | I29: =([20]Main!$J$5-[20]Main!$J$6)*EUR -> -7904.421 | J29: =H29-I29 -> 55080.171 | K29: Q125 | L29: 435 | M29: 45822
A30: x | D30: =+D29+1 -> 20 | E30: Bayer | F30: BAYN | G30: 27.4 | H30: =+G30*L30*EUR -> 29879.322 | I30: =([21]Main!$J$5-[21]Main!$J$6) -> -34255 | J30: =+H30-I30 -> 64134.322 | K30: Q125 | L30: =+[21]Main!$J$3 -> 982.42 | M30: 45822
A31: x | D31: =+D30+1 -> 21 | E31: Regeneron | F31: REGN | G31: 571.62 | H31: =+G31*L31 -> 63564.144 | I31: =+[22]Main!$J$5-[22]Main!$J$6 -> 15641 | J31: =H31-I31 -> 47923.144 | K31: Q125 | L31: =+[22]Main!$J$3 -> 111.2 | M31: 45776 | AE31: 1988
A32: x | D32: =+D31+1 -> 22 | E32: Sun Pharmaceuticals | F32: SUNP | G32: 1641.6 | H32: {=+G32*L32/INR} -> 47706.825 | I32: =([23]Main!$J$5-[23]Main!$J$6)/INR -> 361.34101 | J32: =H32-I32 -> 47345.484 | K32: Q224 | L32: =+[23]Main!$J$3 -> 2399 | M32: 45537 | AE32: 1983
A33: x | D33: =+D32+1 -> 23 | E33: Samsung Biologics | F33: 207940 KS | G33: 1048000 | H33: =+G33*L33/KRW -> 52051.886 | I33: =([24]Main!$M$5-[24]Main!$M$6)/KRW*1000 -> 439.56164 | J33: =+H33-I33 -> 51612.324 | K33: Q124 | L33: =+[24]Main!$M$3 -> 71.174 | M33: 45536
A34: x | D34: =+D33+1 -> 24 | E34: Daiichi Sankyo | F34: 4568 JP | G34: 3620 | H34: =+G34*L34/JPY -> 47710.798 | I34: =([25]Main!$M$5-[25]Main!$M$6)*1000/JPY -> 6914.7608 | J34: =+H34-I34 -> 40796.038 | K34: Q224 | L34: =+[25]Main!$M$3 -> 1914.3628 | M34: 45535
A35: x | D35: =+D34+1 -> 25 | E35: UCB | F35: UCB | G35: 184.65 | H35: =+G35*L35*EUR -> 38942.685 | I35: =([26]Main!$J$5-[26]Main!$J$6)*EUR -> -2901.54 | J35: =H35-I35 -> 41844.225 | K35: Q224 | L35: =+[26]Main!$J$3 -> 190 | M35: 45537
A36: x | D36: =+D35+1 -> 26 | E36: Teva | F36: TEVA | G36: 15.9 | H36: =+G36*L36 -> 18014.7 | I36: =+[27]Main!$M$5-[27]Main!$M$6 -> -16382 | J36: =+H36-I36 -> 34396.7 | K36: Q125 | L36: =+[27]Main!$M$3 -> 1133 | M36: 45793
A37: x | D37: =+D36+1 -> 27 | E37: Alnylam | F37: ALNY | G37: 420.99 | H37: =+G37*L37 -> 54859.628 | I37: =+[28]Main!$L$5-[28]Main!$L$6 -> 1606.656 | J37: =H37-I37 -> 53252.972 | K37: Q125 | L37: =+[28]Main!$L$3 -> 130.311 | M37: 45821 | AE37: 2002 | AF37: Cambridge, MA
A38: x | D38: =+D37+1 -> 28 | E38: Argenx | F38: ARGX | G38: 693 | H38: =+G38*L38 -> 41649.3 | I38: =+[29]Main!$K$5-[29]Main!$K$6 -> 3374 | J38: =H38-I38 -> 38275.3 | K38: Q324 | L38: =+[29]Main!$K$3 -> 60.1 | M38: 45757 | AE38: 2008
A39: x | D39: =+D38+1 -> 29 | E39: Baxter | F39: BAX | G39: 22.66 | H39: =+G39*L39 -> 11556.6 | I39: =+[30]Main!$K$5-[30]Main!$K$6 -> -10809 | J39: =+H39-I39 -> 22365.6 | K39: Q224 | L39: =+[30]Main!$K$3 -> 510 | M39: 45536 | AE39: 1931
A40: x | D40: =+D39+1 -> 30 | E40: Galderma | F40: GALD SW | G40: 128.2
A41: x | D41: =+D40+1 -> 31 | E41: Viatris | F41: VTRS | G41: 8.96 | H41: =G41*[31]Main!$M$3 -> 10516.19 | I41: =[31]Main!$M$5-[31]Main!$M$6 -> -13431 | J41: =H41-I41 -> 23947.19 | K41: Q224 | L41: =+[31]Main!$M$3 -> 1173.682 | M41: 45537 | AE41: 1961
...

Sheet Drugs
A1: Main
B2: Brand | C2: Generic | D2: DBID | E2: Target | F2: MOA | G2: MW | H2: FDA | I2: Class | J2: AA
B3: Refludan | C3: lepirudin | D3: 1 | E3: thrombin | F3: peptide inhibitor | G3: 6979 | I3: rhProtein | J3: 65
B4: Erbitux | C4: cetuximab | D4: 2 | E4: EGFR | F4: mab | G4: 145781.6 | I4: mab
B5: Pulmozyme | C5: dornase alfa | D5: 3 | E5: extracellular DNA | F5: recombinant enzyme | G5: 29253.9 | I5: rhProtein | J5: 260
B6: Ontak | C6: denileukin difitox | D6: 4 | E6: IL-2 | F6: protein-toxin conjugate | G6: 58000 | I6: fusion protein | J6: =387+133 -> 520
B7: Enbrel | C7: etanercept | D7: 5 | E7: TNF-alpha | F7: soluble receptor | G7: 51235 | I7: rhProtein | J7: 934
B8: Angiomax | C8: bivalirudin | D8: 6 | E8: thrombin | F8: peptide inhibitor | G8: 2180 | I8: peptide | J8: 20
B9: Lupron | C9: leuprolide | D9: 7 | E9: GnRHR | F9: GnRH analog | G9: 1209 | I9: peptide | J9: 9
B10: Pegasys | C10: peginterferon alfa-2a | D10: 8 | E10: Type 1 IFNR | F10: IFNR agonist | G10: 60000 | I10: rhProtein | J10: 165
B11: Activase | C11: alteplase | D11: 9 | E11: fibrin, plasminogen | F11: recombinant enzyme | G11: 59000 | I11: rhProtein | J11: 527
B12: Geref | C12: sermorelin | D12: 10 | E12: GHRHR | F12: GRF mimetic | G12: 3358 | I12: peptide | J12: 29
B13: Wellferon | C13: interferon alfa-n1 | D13: 11 | E13: Type 1 IFNR | F13: IFNR agonist | G13: 19241 | I13: purified protein | J13: 166
B14: Aranesp | C14: darbepoetin alfa | D14: 12 | E14: EPOR | F14: EPOR agonist | G14: 18396 | I14: rhProtein
B15: Kinlytic | C15: urokinase | D15: 13 | E15: plasminogen | F15: protease | G15: 31126.5 | I15: rhProtein
B16: Zoladex | C16: goserelin | D16: 14 | E16: GnRHR | F16: LHRH analog | G16: 1269 | I16: small molecule | J16: N/A
C17: reteplase | D17: 15 | E17: plasminogen | F17: tPA analog | G17: 39589.6 | I17: rhProtein | J17: 355
B18: Procrit | C18: erythropoietin | D18: 16 | E18: EPOR | F18: EPOR agonist | G18: 18396 | I18: rhProtein | J18: 165
C19: salmon calcitonin | D19: 17 | E19: Calcitonin receptor | F19: calcitonin receptor agonist | G19: 3431.853 | I19: peptide | J19: 32
C20: interferon alfa-n3 | D20: 18 | E20: Type 1 IFNR | F20: IFNR agonist | I20: purified protein | J20: 166
B21: Neulasta | C21: pegfilgrastim | D21: 19 | E21: G-CSF Receptor | F21: G-CSF | G21: 39000 | I21: rhProtein
B22: Leukine | C22: sargramostim | D22: 20 | E22: GM-CSF-R-alpha | F22: GM-CSF | G22: 14434.5 | I22: rhProtein | J22: 127
C23: secretin | D23: 21 | E23: secretin receptor | F23: secretin receptor agonist | G23: 3039 | I23: peptide | J23: 27
C24: peginterferon alfa-2b | D24: 22 | E24: Type 1 IFNR | F24: IFNR agonist | G24: 31000 | I24: rhProtein
B25: Rylaze | C25: asparginase | D25: 23 | E25: L-asparagine | F25: recombinant enzyme
B26: Thyrogen | C26: thyrotropin alfa | D26: 24 | E26: TSH receptor | F26: TSH receptor agonist | G26: 22673 | I26: rhProtein
B27: Advate | C27: antihemophilic factor | D27: 25 | E27: Factor IXa | F27: Factor IXa complex component | G27: 264726 | I27: rhProtein | J27: 2332
B28: Kineret | C28: anakinra | D28: 26 | E28: IL-1 | F28: soluble receptor | G28: 17257.6 | I28: rhProtein | J28: 153
C29: gramicidin D | D29: 27 | G29: 1811.253 | I29: peptide | J29: 15
B30: Gammagard | C30: human immunoglobulin G | D30: 28 | G30: 142682.3 | I30: purified protein
C31: anistreplase | D31: 29 | E31: plasminogen | F31: recombinant enzyme | G31: 59042.3 | I31: rhProtein | J31: 527
B32: Humulin | C32: insulin human | D32: 30 | E32: Insulin Receptor | F32: insulin receptor agonist | G32: 5808 | I32: rhProtein | J32: 51
B33: TNKase | C33: tenecteplase | D33: 31 | E33: plasminogen | F33: tPA analog | G33: 58951.2 | I33: rhProtein | J33: 527
B34: Menopur | C34: menotropins | D34: 32 | E34: FSH receptor | F34: FSH agonist | G34: 23390.3 | I34: purified protein
B35: Actimmune | C35: interferon gamma-1b | D35: 33 | E35: Type 1 IFNR | F35: IFNR agonist | G35: 17145.6 | I35: rhProtein | J35: 140
C36: interferon alfa-2a | D36: 34 | E36: Type 1 IFNR | F36: IFNR agonist | G36: 19241.1 | I36: rhProtein | J36: 165
B37: Ddavp | C37: desmopressin | D37: 35 | E37: V1, V2, V3 receptors | F37: vasopressin receptor agonist | G37: 1069 | I37: peptide | J37: 8
B38: NovoSeven | C38: coagulation factor VIIa recombinant human | D38: 36 | E38: Factor IX, Factor X | F38: recombinant enzyme | G38: 45079
C39: interferon alfa-2a | D39: 37 | E39: Type 1 IFNR | F39: IFNR agonist | G39: 19241.1 | I39: rhProtein | J39: 165
B40: Neumega | C40: oprelvekin | D40: 38 | E40: IL-11 receptor | F40: IL-11 receptor agonist | G40: 19047 | I40: rhProtein | J40: 177
...

Sheet Industry Model
A1: Main
C2: Q123 | D2: Q223 | E2: Q323 | F2: Q423 | G2: Q124 | H2: Q224 | I2: Q324 | J2: Q424 | M2: 2023 | N2: 2024
B3: J&J | G3: 21382 | H3: 22453
B4: Merck | G4: 15775 | H4: 16112
B5: AbbVie | G5: 12310 | H5: 14462
B6: Lilly | G6: 8768 | H6: 11303
B7: Novo | G7: =65349/DKK -> 9260.1672 | H7: =68060/DKK -> 9644.3248
B8: Revenue | C8: =SUM(C3:C7) -> 0 | D8: =SUM(D3:D7) -> 0 | E8: =SUM(E3:E7) -> 0 | F8: =SUM(F3:F7) -> 0 | G8: =SUM(G3:G7) -> 67495.167 | H8: =SUM(H3:H7) -> 73974.325
B9: Lilly COGS | G9: 1534.4 | H9: 2031.1
B10: J&J COGS | G10: 5404 | H10: 6869
B11: AbbVie COGS | G11: 2108 | H11: 2135
B12: Merck COGS | G12: 2961 | H12: 3073
B13: Novo COGS | G13: =9916/DKK -> 1405.1297 | H13: =10274/DKK -> 1455.8594
B14: COGS | G14: =SUM(G9:G13) -> 13412.53 | H14: =SUM(H9:H13) -> 15563.959
B15: Gross Margin | G15: =+G8-G14 -> 54082.638 | H15: =+H8-H14 -> 58410.365
B16: R&D | N16: =SUM(N17:N21) -> 53959.552
B17: Lilly R&D | N17: 9998
B18: AbbVie R&D | N18: 7795
B19: Novo R&D | N19: =45766/7.25 -> 6312.5517
B20: Pfizer R&D | M20: 11988 | N20: 11988
B21: Merck R&D | N21: 17866
B22: Novartis R&D | N22: 9214
B23: J&J R&D
B24: Sanofi R&D
B25: GSK R&D
B26: Amgen R&D
B31: Industry GM% | C31: =+C15/C8 -> #DIV/0! | D31: =+D15/D8 -> #DIV/0! | G31: =+G15/G8 -> 0.80128163 | H31: =+H15/H8 -> 0.78960322

Sheet Todo
B2: ORGO - look at new product for OA
B3: DCTH - assess revenue potential, look at dilutive instruments
B4: QXO - study Brad Jacobs
B5: SAVA - continue
B6: HIMS - listen to conference calls
B7: ABCL - deeper dive
B8: SQ - listen to conference calls, check if new product/pipeline disclosed
B9: JBL - listen to conference calls, model more years, do forecasts, look into customers, compare to macroeconomic data
B10: PCVX - deeper dive, conf calls, patents
B11: SYM - keep an eye on it
B12: CTAS
B13: ACET
... B23: TRVI - dig deeper

Sheet Launches
A1: Main | AN1: =AVERAGE(AN3:AN4,AN6:AN34,AN36:AN52) -> 291.80038
A2: # | B2: Drug | C2: Company | D2: Indication | E2: # in Class | F2: Launch | G2: Lifetime | I2: Y1 | J2: Y2 | K2: Y3 | L2: Y4 | M2: Y5 | N2: Y6 | O2: Y7 | P2: Y8 | Q2: Y9 | R2: Y10 | S2: Y11 | T2: Y12 | U2: Y13 | V2: Y14 | W2: Y15 | X2: Y16 | Y2: Y17 | Z2: Y18 | AA2: Y19 | AB2: Y20 | AC2: Y21 | AD2: Y22 | AE2: Y23 | AF2: Y24 | AG2: Y25 | AH2: Y26 | AK2: Q1 | AL2: Q2 | AM2: Q3 | AN2: Q4 | AO2: Q5 | AP2: Q6 | AQ2: Q7 | AR2: Q8 | AS2: Q9 | AT2: Q10 | AU2: Q11 | AV2: Q12 | AW2: Q13 | AX2: Q14 | AY2: Q15 | AZ2: Q16 | BA2: Q17 | BB2: Q18 | BC2: Q19 | BD2: Q20 | BE2: Q21 | BF2: Q22 | BG2: Q23 | BH2: Q24 | BI2: Q25 | BJ2: Q26 | BK2: Q27 | BL2: Q28 | BM2: Q29
A3: 1 | B3: Humira | C3: ABBV | D3: Autoimmune | E3: 3 | F3: Q103 | G3: =SUM(AK3:GH3) -> 233470 | I3: =SUM(AK3:AN3) -> 280 | J3: =SUM(AO3:AR3) -> 852 | K3: =SUM(AS3:AV3) -> 1400 | L3: =SUM(AW3:AZ3) -> 2044 | M3: =SUM(BA3:BD3) -> 3063 | N3: =SUM(BE3:BH3) -> 4522 | O3: =SUM(BI3:BL3) -> 5488 | P3: =SUM(BM3:BP3) -> 6548 | Q3: =SUM(BQ3:BT3) -> 7932 | R3: =SUM(BU3:BX3) -> 9266 | S3: =SUM(BY3:CB3) -> 10659 | T3: =SUM(CC3:CF3) -> 12543 | U3: =SUM(CG3:CJ3) -> 14012 | V3: =SUM(CK3:CN3) -> 16078 | W3: =SUM(CO3:CR3) -> 18427 | X3: =SUM(CS3:CV3) -> 19936 | AK3: 30 | AL3: 60 | AM3: 80 | AN3: 110 | AO3: 149 | AP3: 203 | AQ3: 227 | AR3: 273 | AS3: 282 | AT3: 321 | AU3: 356 | AV3: 441 | AW3: 392 | AX3: 491 | AY3: 541 | AZ3: 620 | BA3: 571 | BB3: 735 | BC3: 803 | BD3: 954 | BE3: 878 | BF3: 1089 | BG3: 1204 | BH3: 1351 | BI3: 1024 | BJ3: 1311 | BK3: 1491 | BL3: 1662 | BM3: 1397 | BN3: 1593 | BO3: 1679 | BP3: 1879 | BQ3: 1646 | BR3: 1997 | BS3: 2111 | BT3: 2178 | BU3: 1934 | BV3: 2326 | BW3: 2325 | BX3: 2681 | BY3: 2244 | BZ3: 2606 | CA3: 2770 | CB3: 3039 | CC3: 2637 | CD3: 3288 | CE3: 3255 | CF3: 3363 | CG3: 3111 | CH3: 3537 | CI3: 3647 | CJ3: 3717 | CK3: 3577 | CL3: 4149 | CM3: 4060 | CN3: 4292 | CO3: 4118 | CP3: 4716 | CQ3: 4701 | CR3: 4892 | CS3: 4709 | CT3: 5185 | CU3: 5124 | CV3: 4918 | CW3: 4446 | CX3: 4870 | CY3: 4936 | CZ3: 4917 | DA3: 4703 | DB3: 4837 | DC3: 5140 | DD3: 5152 | DE3: 4867 | DF3: 5068 | DG3: 5425 | DH3: 5334 | DI3: 4736 | DJ3: 5363 | DK3: 5559 | DL3: 5579 | DM3: 3541 | DN3: 4012 | DO3: 3547 | DP3: 3304 | DQ3: 2270 | DR3: 2814
A4: =+A12+1 -> 4 | B4: Remicade US | C4: JNJ | D4: Autoimmune | E4: 1 | G4: =SUM(AK4:GH4) -> 92404 | I4: =SUM(AK4:AN4) -> 115 | J4: =SUM(AO4:AR4) -> 370 | K4: =SUM(AS4:AV4) -> 721 | L4: =SUM(AW4:AZ4) -> 1297 | M4: =SUM(BA4:BD4) -> 1730 | N4: =SUM(BE4:BH4) -> 2146 | O4: =SUM(BI4:BL4) -> 2535 | P4: =SUM(BM4:BP4) -> 3014 | Q4: =SUM(BQ4:BT4) -> 3327 | R4: =SUM(BU4:BX4) -> 3748 | S4: =SUM(BY4:CB4) -> 4304 | T4: =SUM(CC4:CF4) -> 4610 | U4: =SUM(CG4:CJ4) -> 5492 | V4: =SUM(CK4:CN4) -> 6139 | AK4: 21 | AL4: 26 | AM4: 27 | AN4: 41 | AO4: 49 | AP4: 91.2 | AQ4: 90.8 | AR4: 139 | AS4: 131 | AT4: 171 | AU4: 209 | AV4: 210 | AW4: 245 | AX4: 332 | AY4: 341 | AZ4: 379 | BA4: 409 | BB4: 421 | BC4: 444 | BD4: 456 | BE4: 464 | BF4: 539 | BG4: 545 | BH4: 598 | BI4: 577 | BJ4: 642 | BK4: 624 | BL4: 692 | BM4: 681 | BN4: 777 | BO4: 776 | BP4: 780 | BQ4: 731 | BR4: 869 | BS4: 819 | BT4: 908 | BU4: 998 | BV4: 886 | BW4: 978 | BX4: 886 | BY4: 1028 | BZ4: 1102 | CA4: 1036 | CB4: 1138 | CC4: 1186 | CD4: 1130 | CE4: 1229 | CF4: 1065 | CG4: 1285 | CH4: 1371 | CI4: 1408 | CJ4: 1428 | CK4: 1521 | CL4: 1523 | CM4: 1591 | CN4: 1504 | CO4: 1600 | CP4: 1672 | CQ4: 1689 | CR4: 1712 | CS4: 1610 | CT4: 1804 | CU4: 1782 | CV4: 1672 | CW4: 1600 | CX4: 1668 | CY4: 1613 | CZ4: 1680 | DA4: 1779 | DB4: 1780 | DC4: 1783 | DD4: 1624 | DE4: 1672 | DF4: 1530 | DG4: 1647 | DH4: 1466 | DI4: 1389 | DJ4: 1320 | DK4: 1379 | DL4: 1238 | DM4: 1102 | DN4: 1107 | DO4: 1136 | DP4: 1035 | DQ4: 990 | DR4: 935 | DS4: 921 | DT4: 901 | DU4: 777 | DV4: 888 | DW4: 761 | DX4: 764 | DY4: 663 | DZ4: 647 | EA4: 558 | EB4: 475 | EC4: 487
A5: =+A4+1 -> 5 | B5: Comirnaty | C5: PFE | D5: Vaccine | G5: =SUM(AK5:GH5) -> 86510 | I5: =SUM(AK5:AN5) -> 24431 | J5: =SUM(AO5:AR5) -> 38981 | K5: =SUM(AS5:AV5) -> 17188 | L5: =SUM(AW5:AZ5) -> 5910 | M5: =SUM(BA5:BD5) -> 0 | N5: =SUM(BE5:BH5) -> 0 | O5: =SUM(BI5:BL5) -> 0 | P5: =SUM(BM5:BP5) -> 0 | Q5: =SUM(BQ5:BT5) -> 0 | R5: =SUM(BU5:BX5) -> 0 | S5: =SUM(BY5:CB5) -> 0 | T5: =SUM(CC5:CF5) -> 0 | U5: =SUM(CG5:CJ5) -> 0 | V5: =SUM(CK5:CN5) -> 0 | AK5: 154 | AL5: 3462 | AM5: 7838 | AN5: 12977 | AO5: 12504 | AP5: 13227 | AQ5: 8848 | AR5: 4402 | AS5: 11329 | AT5: 3064 | AU5: 1488 | AV5: 1307 | AW5: 5361 | AX5: 354 | AY5: 195
A6: =+A8+1 -> 10 | B6: Biktarvy | C6: GILD | D6: HIV | G6: =SUM(AK6:GH6) -> 50224 | I6: =SUM(AK6:AN6) -> 1184 | J6: =SUM(AO6:AR6) -> 4738 | K6: =SUM(AS6:AV6) -> 7259 | L6: =SUM(AW6:AZ6) -> 8624 | M6: =SUM(BA6:BD6) -> 10391 | N6: =SUM(BE6:BH6) -> 11850 | O6: =SUM(BI6:BL6) -> 6178 | P6: =SUM(BM6:BP6) -> 0 | Q6: =SUM(BQ6:BT6) -> 0 | R6: =SUM(BU6:BX6) -> 0 | S6: =SUM(BY6:CB6) -> 0 | T6: =SUM(CC6:CF6) -> 0 | U6: =SUM(CG6:CJ6) -> 0 | V6: =SUM(CK6:CN6) -> 0 | AK6: 35 | AL6: 185 | AM6: 386 | AN6: 578 | AO6: 793 | AP6: 1116 | AQ6: 1259 | AR6: 1570 | AS6: 1693 | AT6: 1604 | AU6: 1891 | AV6: 2071 | AW6: 1824 | AX6: 1994 | AY6: 2276 | AZ6: 2530 | BA6: 2151 | BB6: 2556 | BC6: 2766 | BD6: 2918 | BE6: 2677 | BF6: 2979 | BG6: 3085 | BH6: 3109 | BI6: 2946 | BJ6: 3232
A7: =+A11+1 -> 19 | B7: Harvony | C7: GILD | D7: HCV | G7: =SUM(AK7:GH7) -> 31975 | I7: =SUM(AK7:AN7) -> 9314 | J7: =SUM(AO7:AR7) -> 12258 | K7: =SUM(AS7:AV7) -> 6253 | L7: =SUM(AW7:AZ7) -> 2296 | M7: =SUM(BA7:BD7) -> 961 | N7: =SUM(BE7:BH7) -> 404 | O7: =SUM(BI7:BL7) -> 211 | P7: =SUM(BM7:BP7) -> 152 | Q7: =SUM(BQ7:BT7) -> 86 | R7: =SUM(BU7:BX7) -> 40 | S7: =SUM(BY7:CB7) -> 0 | T7: =SUM(CC7:CF7) -> 0 | U7: =SUM(CG7:CJ7) -> 0 | V7: =SUM(CK7:CN7) -> 0 | AK7: 20 | AL7: 2107 | AM7: 3579 | AN7: 3608 | AO7: 3332 | AP7: 3345 | AQ7: 3017 | AR7: 2564 | AS7: 1860 | AT7: 1640 | AU7: 1371 | AV7: 1382 | AW7: 973 | AX7: 644 | AY7: 348 | AZ7: 331 | BA7: 311 | BB7: 232 | BC7: 225 | BD7: 193 | BE7: 124 | BF7: 101 | BG7: 112 | BH7: 67 | BI7: 84 | BJ7: 9 | BK7: 56 | BL7: 62 | BM7: 45 | BN7: 49 | BO7: 35 | BP7: 23 | BQ7: 25 | BR7: 31 | BS7: 15 | BT7: 15 | BU7: 23 | BV7: 17
A8: =+A16+1 -> 9 | B8: Opdivo | C8: BMY | D8: Oncology | E8: 1 | G8: =SUM(AK8:GH8) -> 59847 | I8: 942 | J8: 3774 | K8: 4948 | L8: 6735 | M8: 7204 | N8: 6992 | O8: 7523 | P8: =SUM(BM8:BP8) -> 7879 | Q8: =SUM(BQ8:BT8) -> 8610 | R8: =SUM(BU8:BX8) -> 9127 | S8: =SUM(BY8:CB8) -> 0 | T8: =SUM(CC8:CF8) -> 0 | U8: =SUM(CG8:CJ8) -> 0 | V8: =SUM(CK8:CN8) -> 0 | AK8: 1 | AL8: 5 | AM8: 40 | AN8: 122 | AO8: 305 | AP8: 475 | AQ8: 704 | AR8: 840 | AS8: 920 | AT8: 1310 | AU8: 1127 | AV8: 1195 | AW8: 1265 | AX8: 1361 | AY8: 1511 | AZ8: 1627 | BA8: 1793 | BB8: 1804 | BC8: 1801 | BD8: 1823 | BE8: 1817 | BF8: 1763 | BG8: 1766 | BH8: 1653 | BI8: 1780 | BJ8: 1793 | BK8: 1720 | BL8: 1910 | BM8: 1905 | BN8: 1988 | BO8: 1923 | BP8: 2063 | BQ8: 2047 | BR8: 2216 | BS8: 2202 | BT8: 2145 | BU8: 2275 | BV8: 2387 | BW8: 2078 | BX8: 2387
A9: =+A33+1 -> 23 | B9: Genvoya | C9: GILD | D9: HIV | G9: =SUM(AK9:GH9) -> 25283 | I9: =SUM(AK9:AN9) -> 966 | J9: =SUM(AO9:AR9) -> 3177 | K9: =SUM(AS9:AV9) -> 4478 | L9: =SUM(AW9:AZ9) -> 4179 | M9: =SUM(BA9:BD9) -> 3444 | N9: =SUM(BE9:BH9) -> 2975 | O9: =SUM(BI9:BL9) -> 2520 | P9: =SUM(BM9:BP9) -> 2184 | Q9: =SUM(BQ9:BT9) -> 1360 | R9: =SUM(BU9:BX9) -> 0 | S9: =SUM(BY9:CB9) -> 0 | T9: =SUM(CC9:CF9) -> 0 | U9: =SUM(CG9:CJ9) -> 0 | V9: =SUM(CK9:CN9) -> 0 | AK9: 45 | AL9: 158 | AM9: 302 | AN9: 461 | AO9: 563 | AP9: 769 | AQ9: 857 | AR9: 988 | AS9: 1060 | AT9: 1082 | AU9: 1160 | AV9: 1176 | AW9: 1206 | AX9: 1015 | AY9: 980 | AZ9: 978 | BA9: 958 | BB9: 824 | BC9: 816 | BD9: 846 | BE9: 852 | BF9: 673 | BG9: 706 | BH9: 744 | BI9: 756 | BJ9: 582 | BK9: 582 | BL9: 600 | BM9: 640 | BN9: 501 | BO9: 540 | BP9: 503 | BQ9: 517 | BR9: 403 | BS9: 440
A10: 2 | B10: Lipitor | C10: PFE | D10: Cardiovascular | F10: Q197 | G10: =SUM(AK10:GH10) -> 146735 | I10: =SUM(AK10:AN10) -> 865 | J10: =SUM(AO10:AR10) -> 2208 | K10: =SUM(AS10:AV10) -> 3796 | L10: =SUM(AW10:AZ10) -> 5031 | M10: =SUM(BA10:BD10) -> 6449 | N10: =SUM(BE10:BH10) -> 7972 | O10: =SUM(BI10:BL10) -> 9230 | P10: =SUM(BM10:BP10) -> 10862 | Q10: =SUM(BQ10:BT10) -> 12187 | R10: =SUM(BU10:BX10) -> 12886 | S10: =SUM(BY10:CB10) -> 12675 | T10: =SUM(CC10:CF10) -> 12401 | U10: =SUM(CG10:CJ10) -> 11434 | V10: =SUM(CK10:CN10) -> 10733 | W10: =SUM(CO10:CR10) -> 9577 | X10: =SUM(CS10:CV10) -> 3948 | AK10: 49 | AL10: 151 | AM10: 257 | AN10: 408 | AO10: 375 | AP10: 536 | AQ10: 578 | AR10: 719 | AS10: 767 | AT10: 900 | AU10: 995 | AV10: 1134 | AW10: 1119 | AX10: 1262 | AY10: 1216 | AZ10: 1434 | BA10: 1467 | BB10: 1439 | BC10: 1660 | BD10: 1883 | BE10: 1852 | BF10: 1783 | BG10: 2020 | BH10: 2317 | BI10: 2099 | BJ10: 2015 | BK10: 2468 | BL10: 2648 | BM10: 2497 | BN10: 2363 | BO10: 2738 | BP10: 3264 | BQ10: 3075 | BR10: 2858 | BS10: 2897 | BT10: 3357 | BU10: 3107 | BV10: 3123 | BW10: 3321 | BX10: 3335 | BY10: 3358 | BZ10: 2719 | CA10: 3170 | CB10: 3428 | CC10: 3137 | CD10: 2976 | CE10: 3142 | CF10: 3146 | CG10: 2721 | CH10: 2685 | CI10: 2853 | CJ10: 3175 | CK10: 2757 | CL10: 2813 | CM10: 2534 | CN10: 2629 | CO10: 2385 | CP10: 2591 | CQ10: 2602 | CR10: 1999 | CS10: 1395 | CT10: 1220 | CU10: 749 | CV10: 584 | CW10: 626 | CX10: 545 | CY10: 533 | CZ10: 611 | DA10: 457 | DB10: 543 | DC10: 490 | DD10: 572 | DE10: 441 | DF10: 509 | DG10: 454 | DH10: 456 | DI10: 411 | DJ10: 461 | DK10: 422 | DL10: 464 | DM10: 404 | DN10: 445 | DO10: 491 | DP10: 574 | DQ10: 511 | DR10: 521 | DS10: 507 | DT10: 524 | DU10: 622 | DV10: 107 | DW10: 476 | DX10: 468 | DY10: 405 | DZ10: 431
A11: =+A30+1 -> 18 | B11: Ozempic | C11: NOVO | D11: Diabetes | G11: =SUM(AK11:GH11) -> 32529.592 | I11: =SUM(AK11:AN11) -> 769.97085 | J11: =SUM(AO11:AR11) -> 2489.5044 | K11: =SUM(AS11:AV11) -> 3748.8338 | L11: =SUM(AW11:AZ11) -> 6704.3732 | M11: =SUM(BA11:BD11) -> 10948.542 | N11: =SUM(BE11:BH11) -> 7868.3673 | O11: =SUM(BI11:BL11) -> 0 | P11: =SUM(BM11:BP11) -> 0 | Q11: =SUM(BQ11:BT11) -> 0 | R11: =SUM(BU11:BX11) -> 0 | S11: =SUM(BY11:CB11) -> 0 | T11: =SUM(CC11:CF11) -> 0 | U11: =SUM(CG11:CJ11) -> 0 | V11: =SUM(CK11:CN11) -> 0 | AK11: =540/$C$71 -> 78.717201 | AL11: =992/$C$71 -> 144.60641 | AM11: =1425/$C$71 -> 207.72595 | AN11: =2325/$C$71 -> 338.92128 | AO11: =3122/$C$71 -> 455.10204 | AP11: =4365/$C$71 -> 636.29738 | AQ11: =4755/$C$71 -> 693.14869 | AR11: =4836/$C$71 -> 704.95627 | AS11: =5432/$C$71 -> 791.83673 | AT11: =6188/$C$71 -> 902.04082 | AU11: =6662/$C$71 -> 971.13703 | AV11: =7435/$C$71 -> 1083.8192 | AW11: =8892/$C$71 -> 1296.2099 | AX11: =10716/$C$71 -> 1562.0991 | AY11: =12035/$C$71 -> 1754.3732 | AZ11: =14349/$C$71 -> 2091.691 | BA11: =16390/$C$71 -> 2389.2128 | BB11: =16976/$C$71 -> 2474.6356 | BC11: =19640/$C$71 -> 2862.9738 | BD11: =22101/C71 -> 3221.7201 | BE11: =23912/C71 -> 3485.7143 | BF11: =30065/C71 -> 4382.6531
A12: 3 | B12: Eliquis WW | C12: PFE/BMY | D12: Cardiovascular | E12: 2 | F12: Q113 | G12: =+G78+G79 -> 118779 | I12: =+I78+I79 -> 412 | J12: =+J78+J79 -> 1562 | K12: =+K78+K79 -> 3260 | L12: =+L78+L79 -> 5005 | M12: =+M78+M79 -> 7395 | N12: =+N78+N79 -> 9872 | O12: =+O78+O79 -> 12149 | P12: =+P78+P79 -> 13881 | ... V12: =+V78+V79 -> 0
A13: =+A27+1 -> 14 | B13: Ibrance | C13: PFE | D13: Oncology | E13: 1 | G13: =SUM(AK13:GH13) -> 37946 | I13: =SUM(AK13:AN13) -> 723 | J13: =SUM(AO13:AR13) -> 2136 | K13: =SUM(AS13:AV13) -> 3126 | L13: =SUM(AW13:AZ13) -> 4118 | M13: =SUM(BA13:BD13) -> 4960 | N13: =SUM(BE13:BH13) -> 5390 | O13: =SUM(BI13:BL13) -> 5437 | P13: =SUM(BM13:BP13) -> 5119 | Q13: =SUM(BQ13:BT13) -> 4753 | R13: =SUM(BU13:BX13) -> 2184 | S13: =SUM(BY13:CB13) -> 0 | T13: =SUM(CC13:CF13) -> 0 | U13: =SUM(CG13:CJ13) -> 0 | V13: =SUM(CK13:CN13) -> 0 | AK13: 38 | AL13: 140 | AM13: 230 | AN13: 315 | AO13: 429 | AP13: 514 | AQ13: 550 | AR13: 643 | AS13: 679 | AT13: 853 | AU13: 878 | AV13: 716 | AW13: 933 | AX13: 1027 | AY13: 1025 | AZ13: 1133 | BA13: 1133 | BB13: 1261 | BC13: 1283 | BD13: 1283 | BE13: 1248 | BF13: 1349 | BG13: 1357 | BH13: 1436 | BI13: 1254 | BJ13: 1404 | BK13: 1381 | BL13: 1398 | BM13: 1237 | BN13: 1320 | BO13: 1283 | BP13: 1279 | BQ13: 1144 | BR13: 1247 | BS13: 1244 | BT13: 1118 | BU13: 1054 | BV13: 1130
A14: 2 | B14: Keytruda | C14: MRK | D14: Oncology | E14: 2 | F14: Q314 | G14: =SUM(AK14:GH14) -> 123247 | I14: =SUM(AK14:AN14) -> 247 | J14: =SUM(AO14:AR14) -> 936 | K14: =SUM(AS14:AV14) -> 2304 | L14: =SUM(AW14:AZ14) -> 5475 | M14: =SUM(BA14:BD14) -> 8943 | N14: =SUM(BE14:BH14) -> 12853 | O14: =SUM(BI14:BL14) -> 15783 | P14: =SUM(BM14:BP14) -> 19172 | Q14: =SUM(BQ14:BT14) -> 22942 | R14: =SUM(BU14:BX14) -> 27163 | S14: =SUM(BY14:CB14) -> 7429 | T14: =SUM(CC14:CF14) -> 0 | U14: =SUM(CG14:CJ14) -> 0 | V14: =SUM(CK14:CN14) -> 0 | AK14: 4 | AL14: 50 | AM14: 83 | AN14: 110 | AO14: 159 | AP14: 214 | AQ14: 249 | AR14: 314 | AS14: 356 | AT14: 483 | AU14: 584 | AV14: 881 | AW14: 1047 | AX14: 1297 | AY14: 1464 | AZ14: 1667 | BA14: 1889 | BB14: 2151 | BC14: 2269 | BD14: 2634 | BE14: 3070 | BF14: 3111 | BG14: 3284 | BH14: 3388 | BI14: 3715 | BJ14: 3993 | BK14: 3899 | BL14: 4176 | BM14: 4534 | BN14: 4577 | BO14: 4809 | BP14: 5252 | BQ14: 5426 | BR14: 5450 | BS14: 5795 | BT14: 6271 | BU14: 6338 | BV14: 6608 | BW14: 6947 | BX14: 7270 | BY14: 7429
A15: =+A32+1 -> 7 | B15: Januvia+Janumet | C15: MRK | D15: Diabetes | E15: 1 | G15: =SUM(AK15:GH15) -> 74776.5 | I15: =SUM(AK15:AN15) -> 589 | J15: =SUM(AO15:AR15) -> 1600.5 | K15: =SUM(AS15:AV15) -> 2095 | L15: =SUM(AW15:AZ15) -> 3327 | M15: =SUM(BA15:BD15) -> 4488 | N15: =SUM(BE15:BH15) -> 5589 | O15: =SUM(BI15:BL15) -> 5912 | P15: =SUM(BM15:BP15) -> 6073 | Q15: =SUM(BQ15:BT15) -> 6172 | R15: =SUM(BU15:BX15) -> 6087 | S15: =SUM(BY15:CB15) -> 5937 | T15: =SUM(CC15:CF15) -> 5907 | U15: =SUM(CG15:CJ15) -> 5483 | V15: =SUM(CK15:CN15) -> 5346 | AK15: =AK80+AK81 -> 66 | AL15: =AL80+AL81 -> 106 | AM15: =AM80+AM81 -> 174 | AN15: =AN80+AN81 -> 243 | AO15: =AO80+AO81 -> 272 | AP15: =AP80+AP81 -> 373 | AQ15: =AQ80+AQ81 -> 448.5 | AR15: =AR80+AR81 -> 507 | ... CZ15: =CZ80+CZ81 -> 0
A16: =+A15+1 -> 8 | B16: Zyprexa | C16: LLY | D16: Psychiatry | G16: =SUM(AK16:GH16) -> 63086.7 | I16: =SUM(AK16:AN16) -> 550.2 | J16: =SUM(AO16:AR16) -> 1278 | K16: =SUM(AS16:AV16) -> 1726.1 | L16: =SUM(AW16:AZ16) -> 2246.6 | M16: =SUM(BA16:BD16) -> 2882.4 | N16: =SUM(BE16:BH16) -> 3604.1 | O16: =SUM(BI16:BL16) -> 4128.1 | P16: =SUM(BM16:BP16) -> 4479.8 | Q16: =SUM(BQ16:BT16) -> 4255.6 | R16: =SUM(BU16:BX16) -> 4239.3 | S16: =SUM(BY16:CB16) -> 4643.6 | T16: =SUM(CC16:CF16) -> 4823.3 | U16: =SUM(CG16:CJ16) -> 4695.9 | V16: =SUM(CK16:CN16) -> 5057.1 | AK16: 87 | AL16: 105.4 | AM16: 156 | AN16: 201.8 | AO16: 267 | AP16: 287 | AQ16: 328 | AR16: 396 | AS16: 429 | AT16: 401.2 | AU16: 393 | AV16: 502.9 | AW16: 592.9 | AX16: 458.1 | AY16: 550.7 | AZ16: 644.9 | BA16: 696.3 | BB16: 637 | BC16: 736.6 | BD16: 812.5 | BE16: 903.9 | BF16: 819.4 | BG16: 906.8 | BH16: 974 | BI16: 989.8 | BJ16: 958.3 | BK16: 1050 | BL16: 1130 | BM16: 1145.5 | BN16: 1098.3 | BO16: 1212.3 | BP16: 1023.7 | BQ16: 1085.5 | BR16: 1038.2 | BS16: 1096.8 | BT16: 1035.1 | BU16: 1032.2 | BV16: 1007.4 | BW16: 1115 | BX16: 1084.7 | BY16: 1156.5 | BZ16: 1108 | CA16: 1213 | CB16: 1166.1 | CC16: 1273.9 | CD16: 1120.2 | CE16: 1239.7 | CF16: 1189.5 | CG16: 1146.7 | CH16: 1123 | CI16: 1203.2 | CJ16: 1223 | CK16: 1366.5 | CL16: 1215 | CM16: 1262.9 | CN16: 1212.7 | CO16: 1335.8 | CP16: 1281.9 | CQ16: 1408.3 | CR16: 1182.3 | CS16: 749.6 | CT16: 562.7 | CU16: 379.5 | CV16: 374.5 | CW16: 384.8 | CX16: 284.8 | CY16: 283.2 | CZ16: 278.7 | DA16: 348.2 | DB16: 283.1 | DC16: 243.8 | DD16: 257.4 | DE16: 253.1 | DF16: 219.5 | DG16: 253.7 | DH16: 237.9 | DI16: 229.1 | DJ16: 212.8 | DK16: 210.7 | DL16: 148.9 | DM16: 153 | DN16: 147.5 | DO16: 140.8 | DP16: 140.6 | DQ16: 152.2 | DR16: 122.6 | DS16: 128 | DT16: 109.9 | DU16: 110.8 | DV16: 107.2 | DW16: 104.3 | DX16: 105.4 | DY16: 101.8 | DZ16: 98.4 | EA16: 96.6 | EB16: 112.7 | EC16: 98.9 | ED16: 95.8 | EE16: 95.4 | EF16: 101.7 | EG16: 137.4 | EH16: 93.1 | EI16: 87.3 | EJ16: 81.4 | EK16: 75.1 | EL16: 106.5 | EM16: 106.5 | EN16: 61.4 | EO16: 0 | EP16: 0 | EQ16: 0
A17: =+A23+1 -> 28 | B17: Sovaldi | C17: GILD | D17: HCV | G17: =SUM(AK17:GH17) -> 20663.11 | I17: =SUM(AK17:AN17) -> 8690.11 | J17: =SUM(AO17:AR17) -> 5461 | K17: =SUM(AS17:AV17) -> 5007 | L17: =SUM(AW17:AZ17) -> 1388 | M17: =SUM(BA17:BD17) -> 117 | N17: =SUM(BE17:BH17) -> 0 | O17: =SUM(BI17:BL17) -> 0 | P17: =SUM(BM17:BP17) -> 0 | Q17: =SUM(BQ17:BT17) -> 0 | R17: =SUM(BU17:BX17) -> 0 | S17: =SUM(BY17:CB17) -> 0 | T17: =SUM(CC17:CF17) -> 0 | U17: =SUM(CG17:CJ17) -> 0 | V17: =SUM(CK17:CN17) -> 0 | AK17: 139.435 | AL17: 2274.349 | AM17: 3480.326 | AN17: 2796 | AO17: 1732 | AP17: 972 | AQ17: 1291 | AR17: 1466 | AS17: 1547 | AT17: 1277 | AU17: 1358 | AV17: 825 | AW17: 541 | AX17: 313 | AY17: 315 | AZ17: 219 | BA17: 117
A18: =+A22+1 -> 25 | B18: Skyrizi | C18: ABBV | D18: Autoimmune | G18: =SUM(AK18:GH18) -> 22547 | I18: =SUM(AK18:AN18) -> 655 | J18: =SUM(AO18:AR18) -> 1864 | K18: =SUM(AS18:AV18) -> 3305 | L18: =SUM(AW18:AZ18) -> 5585 | M18: =SUM(BA18:BD18) -> 8411 | N18: =SUM(BE18:BH18) -> 2727 | O18: =SUM(BI18:BL18) -> 0 | P18: =SUM(BM18:BP18) -> 0 | Q18: =SUM(BQ18:BT18) -> 0 | R18: =SUM(BU18:BX18) -> 0 | S18: =SUM(BY18:CB18) -> 0 | T18: =SUM(CC18:CF18) -> 0 | U18: =SUM(CG18:CJ18) -> 0 | V18: =SUM(CK18:CN18) -> 0 | AK18: 48 | AL18: 91 | AM18: 216 | AN18: 300 | AO18: 330 | AP18: 435 | AQ18: 525 | AR18: 574 | AS18: 674 | AT18: 796 | AU18: 895 | AV18: 940 | AW18: 1252 | AX18: 1397 | AY18: 1576 | AZ18: 1360 | BA18: 1883 | BB18: 2126 | BC18: 2394 | BD18: 2008 | BE18: 2727
A19: =+A40+1 -> 34 | B19: Vyvgart | C19: ARGX | D19: Autoimmune | E19: 1 | G19: =SUM(AK19:GH19) -> 3777.482 | I19: =SUM(AK19:AN19) -> 400.721 | J19: =SUM(AO19:AR19) -> 1190.761 | K19: =SUM(AS19:AV19) -> 2186 | L19: =SUM(AW19:AZ19) -> 0 | M19: =SUM(BA19:BD19) -> 0 | AK19: 21.163 | AL19: 74.833 | AM19: 131.329 | AN19: 173.396 | AO19: 218 | AP19: 269.313 | AQ19: 329.097 | AR19: 374.351 | AS19: =876-477.635 -> 398.365 | AT19: =876-AS19 -> 477.635 | AU19: 573 | AV19: 737
A20: =+A31+1 -> 21 | B20: Cosentyx | C20: NVS | D20: Autoimmune | F20: Q115 | G20: =SUM(AK20:GH20) -> 31129 | I20: =SUM(AK20:AN20) -> 209 | J20: =SUM(AO20:AR20) -> 1128 | K20: =SUM(AS20:AV20) -> 2071 | L20: =SUM(AW20:AZ20) -> 2837 | M20: =SUM(BA20:BD20) -> 3551 | N20: =SUM(BE20:BH20) -> 3995 | O20: =SUM(BI20:BL20) -> 4718 | P20: =SUM(BM20:BP20) -> 4788 | Q20: =SUM(BQ20:BT20) -> 4980 | R20: =SUM(BU20:BX20) -> 2852 | S20: =SUM(BY20:CB20) -> 0 | T20: =SUM(CC20:CF20) -> 0 | U20: =SUM(CG20:CJ20) -> 0 | V20: =SUM(CK20:CN20) -> 0 | AK20: 22 | AL20: 30 | AM20: 88 | AN20: 121 | AO20: 176 | AP20: 260 | AQ20: 301 | AR20: 391 | AS20: 410 | AT20: 490 | AU20: 556 | AV20: 615 | AW20: 580 | AX20: 701 | AY20: 750 | AZ20: 806 | BA20: 791 | BB20: 858 | BC20: 937 | BD20: 965 | BE20: 930 | BF20: 944 | BG20: 1012 | BH20: 1109 | BI20: 1053 | BJ20: 1175 | BK20: 1247 | BL20: 1243 | BM20: 1159 | BN20: 1275 | BO20: 1274 | BP20: 1080 | BQ20: 1076 | BR20: 1272 | BS20: 1329 | BT20: 1303 | BU20: 1326 | BV20: 1526
A21: =+A36+1 -> 31 | B21: Rinvoq | C21: ABBV | D21: Autoimmune | G21: =SUM(AK21:GH21) -> 11443 | I21: =SUM(AK21:AN21) -> 282 | J21: =SUM(AO21:AR21) -> 1177 | K21: =SUM(AS21:AV21) -> 2027 | L21: =SUM(AW21:AZ21) -> 3069 | M21: =SUM(BA21:BD21) -> 4888 | N21: =SUM(BE21:BH21) -> 0 | O21: =SUM(BI21:BL21) -> 0 | P21: =SUM(BM21:BP21) -> 0 | Q21: =SUM(BQ21:BT21) -> 0 | R21: =SUM(BU21:BX21) -> 0 | S21: =SUM(BY21:CB21) -> 0 | T21: =SUM(CC21:CF21) -> 0 | U21: =SUM(CG21:CJ21) -> 0 | V21: =SUM(CK21:CN21) -> 0 | AK21: 14 | AL21: 33 | AM21: 86 | AN21: 149 | AO21: 215 | AP21: 281 | AQ21: 303 | AR21: 378 | AS21: 453 | AT21: 517 | AU21: 465 | AV21: 592 | AW21: 695 | AX21: 770 | AY21: 686 | AZ21: 918 | BA21: 1110 | BB21: 1255 | BC21: 1093 | BD21: 1430
A22: =+A9+1 -> 24 | B22: Zytiga | C22: JNJ | D22: Oncology | E22: 1 | G22: =SUM(AK22:GH22) -> 25264.5 | I22: =SUM(AK22:AN22) -> 297.5 | J22: =SUM(AO22:AR22) -> 961 | K22: =SUM(AS22:AV22) -> 1698 | L22: =SUM(AW22:AZ22) -> 2237 | M22: =SUM(BA22:BD22) -> 2231 | N22: =SUM(BE22:BH22) -> 2260 | O22: =SUM(BI22:BL22) -> 2505 | P22: =SUM(BM22:BP22) -> 3498 | Q22: =SUM(BQ22:BT22) -> 2795 | R22: =SUM(BU22:BX22) -> 2470 | S22: =SUM(BY22:CB22) -> 2297 | T22: =SUM(CC22:CF22) -> 1770 | U22: =SUM(CG22:CJ22) -> 245 | V22: =SUM(CK22:CN22) -> 0 | AK22: 5 | AL22: =AVERAGE(AK22,AM22) -> 50 | AM22: 95 | AN22: =AVERAGE(AM22,AO22) -> 147.5 | AO22: 200 | AP22: 232 | AQ22: 265 | AR22: 264 | AS22: 344 | AT22: 395 | AU22: 464 | AV22: 495 | AW22: 512 | AX22: 562 | AY22: 568 | AZ22: 595 | BA22: 556 | BB22: 546 | BC22: 548 | BD22: 581 | BE22: 558 | BF22: 601 | BG22: 582 | BH22: 519 | BI22: 523 | BJ22: 558 | BK22: 669 | BL22: 755 | BM22: 845 | BN22: 909 | BO22: 958 | BP22: 786 | BQ22: 679 | BR22: 698 | BS22: 741 | BT22: 677 | BU22: 690 | BV22: 568 | BW22: 590 | BX22: 622 | BY22: 638 | BZ22: 563 | CA22: 548 | CB22: 548 | CC22: 539 | CD22: 505 | CE22: 456 | CF22: 270 | CG22: 245
A23: =+A35+1 -> 27 | B23: Imbruvica | C23: JNJ | D23: Oncology | E23: 1 | G23: =SUM(AK23:GH23) -> 23168 | I23: =SUM(AK23:AN23) -> 200 | J23: =SUM(AO23:AR23) -> 689 | K23: =SUM(AS23:AV23) -> 1251 | L23: =SUM(AW23:AZ23) -> 1893 | M23: =SUM(BA23:BD23) -> 2615 | N23: =SUM(BE23:BH23) -> 3411 | O23: =SUM(BI23:BL23) -> 4128 | P23: =SUM(BM23:BP23) -> 4369 | Q23: =SUM(BQ23:BT23) -> 3785 | R23: =SUM(BU23:BX23) -> 827 | S23: =SUM(BY23:CB23) -> 0 | T23: =SUM(CC23:CF23) -> 0 | U23: =SUM(CG23:CJ23) -> 0 | V23: =SUM(CK23:CN23) -> 0 | AK23: 10 | AL23: 42 | AM23: 56 | AN23: 92 | AO23: 116 | AP23: 154 | AQ23: 184 | AR23: 235 | AS23: 261 | AT23: 295 | AU23: 349 | AV23: 346 | AW23: 409 | AX23: 450 | AY23: 512 | AZ23: 522 | BA23: 587 | BB23: 620 | BC23: 705 | BD23: 703 | BE23: 784 | BF23: 831 | BG23: 921 | BH23: 875 | BI23: 1031 | BJ23: 949 | BK23: 1031 | BL23: 1117 | BM23: 1125 | BN23: 1116 | BO23: 1066 | BP23: 1062 | BQ23: 1038 | BR23: 970 | BS23: 911 | BT23: 866 | BU23: 827
A24: =+A17+1 -> 29 | B24: Isentress | C24: MRK | D24: HIV | G24: =SUM(AK24:GH24) -> 16856 | I24: =SUM(AK24:AN24) -> 348 | J24: =SUM(AO24:AR24) -> 751 | K24: =SUM(AS24:AV24) -> 1090 | L24: =SUM(AW24:AZ24) -> 1359 | M24: =SUM(BA24:BD24) -> 1515 | N24: =SUM(BE24:BH24) -> 1643 | O24: =SUM(BI24:BL24) -> 1673 | P24: =SUM(BM24:BP24) -> 1511 | Q24: =SUM(BQ24:BT24) -> 1387 | R24: =SUM(BU24:BX24) -> 1205 | S24: =SUM(BY24:CB24) -> 1141 | T24: =SUM(CC24:CF24) -> 975 | U24: =SUM(CG24:CJ24) -> 857 | V24: =SUM(CK24:CN24) -> 768 | AK24: 47 | AL24: 77 | AM24: 107 | AN24: 117 | AO24: 148 | AP24: 172 | AQ24: 197 | AR24: 234 | AS24: 232 | AT24: 267 | AU24: 278 | AV24: 313 | AW24: 292 | AX24: 337 | AY24: 343 | AZ24: 387 | BA24: 337 | BB24: 398 | BC24: 399 | BD24: 381 | BE24: 362 | BF24: 412 | BG24: 427 | BH24: 442 | BI24: 390 | BJ24: 453 | BK24: 412 | BL24: 418 | BM24: 385 | BN24: 375 | BO24: 377 | BP24: 374 | BQ24: 340 | BR24: 338 | BS24: 372 | BT24: 337 | BU24: 305 | BV24: 282 | BW24: 310 | BX24: 308 | BY24: 281 | BZ24: 305 | CA24: 275 | CB24: 280 | CC24: 255 | CD24: 247 | CE24: 250 | CF24: 223 | CG24: 245 | CH24: 196 | CI24: 205 | CJ24: 211 | CK24: 209 | CL24: 192 | CM24: 189 | CN24: 178 | CO24: 158 | CP24: 147 | CQ24: 161 | CR24: 167
A25: =+A6+1 -> 11 | B25: Humalog | C25: LLY | D25: Diabetes | G25: =SUM(AK25:GH25) -> 48471.867 | I25: =SUM(AK25:AN25) -> 11 | J25: =SUM(AO25:AR25) -> 80 | K25: =SUM(AS25:AV25) -> 167.5 | L25: =SUM(AW25:AZ25) -> 280.4 | M25: =SUM(BA25:BD25) -> 472.2 | N25: =SUM(BE25:BH25) -> 739.2 | O25: =SUM(BI25:BL25) -> 954.9 | P25: =SUM(BM25:BP25) -> 1069.6 | Q25: =SUM(BQ25:BT25) -> 1131.6 | R25: =SUM(BU25:BX25) -> 1241.7667 | S25: =SUM(BY25:CB25) -> 1372.1 | T25: =SUM(CC25:CF25) -> 1622 | U25: =SUM(CG25:CJ25) -> 1818.6 | V25: =SUM(CK25:CN25) -> 2042 | W25: =SUM(CO25:CR25) -> 2155.4 | X25: =SUM(CS25:CV25) -> 2458.9 | Y25: =SUM(CW25:CZ25) -> 2453.1 | Z25: =SUM(DA25:DD25) -> 2700 | AA25: =SUM(DE25:DH25) -> 2773.5 | AK25: 1 | AL25: 2 | AM25: 3 | AN25: 5 | AO25: 10 | AP25: 15 | AQ25: 25 | AR25: 30 | AS25: 32 | AT25: 42.6 | AU25: 42.5 | AV25: 50.4 | AW25: 58.7 | AX25: 72.9 | AY25: 72.1 | AZ25: 76.7 | BA25: 90.6 | BB25: 110.8 | BC25: 125.2 | BD25: 145.6 | BE25: 164.3 | BF25: 192.7 | BG25: 177.4 | BH25: 204.8 | BI25: 214.1 | BJ25: 237.9 | BK25: 248.8 | BL25: 254.1 | BM25: 240.2 | BN25: 276.9 | BO25: 267.2 | BP25: 285.3 | BQ25: 264.6 | BR25: 284.6 | BS25: 286.2 | BT25: 296.2 | BU25: 306.66667 | BV25: 309.1 | BW25: 305 | BX25: 321 | BY25: 322 | BZ25: 352.2 | CA25: 339.5 | CB25: 358.4 | CC25: 362.5 | CD25: 414.2 | CE25: 407.4 | CF25: 437.9 | CG25: 432.6 | CH25: 457.9 | CI25: 450.6 | CJ25: 477.5 | CK25: 500.2 | CL25: 530.8 | CM25: 506.4 | CN25: 504.6 | CO25: 494 | CP25: 549.1 | CQ25: 525.4 | CR25: 586.9 | CS25: 593.2 | CT25: 662 | CU25: 590.3 | CV25: 613.4 | CW25: 575.8 | CX25: 616 | CY25: 632.7 | CZ25: 628.6 | DA25: 616 | DB25: 733.9 | DC25: 650 | DD25: 700.1 | DE25: 706.1 | DF25: 729.1 | DG25: 684 | DH25: 654.3 | DI25: 705 | DJ25: 798.7 | DK25: 606.3 | DL25: 701.9 | DM25: 640.8 | DN25: 819.8 | DO25: 708.4 | DP25: 678.4 | DQ25: 696.2 | DR25: 782.2 | DS25: 791.7 | DT25: 769.8 | DU25: 664.6 | DV25: 770.4 | DW25: 730.8 | DX25: 677.6 | DY25: 648.9 | DZ25: 763.4 | EA25: 695.8 | EB25: 555.1 | EC25: 656.9 | ED25: 718.1 | EE25: 617.1 | EF25: 607.6 | EG25: 626.7 | EH25: 601.7 | EI25: 618.2 | EJ25: 447.1 | EK25: 447 | EL25: 548.3 | EM25: 460.9 | EN25: 440.4 | EO25: 395.4 | EP25: 366.6 | EQ25: 538.7 | ER25: 631.6
A26: =+A25+1 -> 12 | B26: Darzalex | C26: JNJ | D26: Oncology | E26: 1 | G26: =SUM(AK26:GH26) -> 43368 | I26: =SUM(AK26:AN26) -> 383 | J26: =SUM(AO26:AR26) -> 1071 | K26: =SUM(AS26:AV26) -> 1812 | L26: =SUM(AW26:AZ26) -> 2752 | M26: =SUM(BA26:BD26) -> 3767 | N26: =SUM(BE26:BH26) -> 5631 | O26: =SUM(BI26:BL26) -> 7539 | P26: =SUM(BM26:BP26) -> 9277 | Q26: =SUM(BQ26:BT26) -> 11136 | R26: =SUM(BU26:BX26) -> 0 | S26: =SUM(BY26:CB26) -> 0 | T26: =SUM(CC26:CF26) -> 0 | U26: =SUM(CG26:CJ26) -> 0 | V26: =SUM(CK26:CN26) -> 0 | AK26: 20 | AL26: 101 | AM26: 108 | AN26: =AVERAGE(AM26,AO26) -> 154 | AO26: 200 | AP26: 255 | AQ26: 299 | AR26: 317 | AS26: 371 | AT26: 432 | AU26: 511 | AV26: 498 | AW26: 584 | AX26: 629 | AY26: 774 | AZ26: 765 | BA26: 830 | BB26: 937 | BC26: 901 | BD26: 1099 | BE26: 1253 | BF26: 1365 | BG26: 1433 | BH26: 1580 | BI26: 1645 | BJ26: 1856 | BK26: 1986 | BL26: 2052 | BM26: 2083 | BN26: 2264 | BO26: 2431 | BP26: 2499 | BQ26: 2550 | BR26: 2692 | BS26: 2878 | BT26: 3016
A27: =+A26+1 -> 13 | B27: Gardasil | C27: MRK | D27: Vaccine, Oncology | E27: 1 | G27: =SUM(AK27:GH27) -> 41658 | I27: =SUM(AK27:AN27) -> 600 | J27: =SUM(AO27:AR27) -> 1616 | K27: =SUM(AS27:AV27) -> 1400 | L27: =SUM(AW27:AZ27) -> 1089 | M27: =SUM(BA27:BD27) -> 970 | N27: =SUM(BE27:BH27) -> 1280 | O27: =SUM(BI27:BL27) -> 1737 | P27: =SUM(BM27:BP27) -> 1825 | Q27: =SUM(BQ27:BT27) -> 1714 | R27: =SUM(BU27:BX27) -> 1927 | S27: =SUM(BY27:CB27) -> 2327 | T27: =SUM(CC27:CF27) -> 2437 | U27: =SUM(CG27:CJ27) -> 3329 | V27: =SUM(CK27:CN27) -> 3996 | AK27: 10 | AL27: 70 | AM27: 155 | AN27: 365 | AO27: 358 | AP27: 418 | AQ27: 450 | AR27: 390 | AS27: 326 | AT27: 401 | AU27: 411 | AV27: 262 | AW27: 268 | AX27: 311 | AY27: 277 | AZ27: 233 | BA27: 219 | BB27: 316 | BC27: 221 | BD27: 214 | BE27: 277 | BF27: 445 | BG27: 274 | BH27: 284 | BI27: 324 | BJ27: 581 | BK27: 442 | BL27: 390 | BM27: 383 | BN27: 665 | BO27: 394 | BP27: 383 | BQ27: 409 | BR27: 590 | BS27: 356 | BT27: 359 | BU27: 427 | BV27: 625 | BW27: 497 | BX27: 378 | BY27: 393 | BZ27: 860 | CA27: 542 | CB27: 532 | CC27: 469 | CD27: 675 | CE27: 633 | CF27: 660 | CG27: 608 | CH27: 1048 | CI27: 835 | CJ27: 838 | CK27: 886 | CL27: 1320 | CM27: 693 | CN27: 1097 | CO27: 656 | CP27: 1187 | CQ27: 998 | CR27: 917 | CS27: 1234 | CT27: 1993 | CU27: 1528 | CV27: 1460 | CW27: 1674 | CX27: 2294 | CY27: 1470
A28: =+A13+1 -> 15 | B28: Viagra | C28: PFE | D28: Cardiovascular | E28: 1 | G28: =SUM(AK28:GH28) -> 34660 | I28: =SUM(AK28:AN28) -> 963 | J28: =SUM(AO28:AR28) -> 1155 | K28: =SUM(AS28:AV28) -> 1393 | L28: =SUM(AW28:AZ28) -> 1563 | M28: =SUM(BA28:BD28) -> 1788 | N28: =SUM(BE28:BH28) -> 1820 | O28: =SUM(BI28:BL28) -> 1699 | P28: =SUM(BM28:BP28) -> 1597 | Q28: =SUM(BQ28:BT28) -> 1701 | R28: =SUM(BU28:BX28) -> 1790 | S28: =SUM(BY28:CB28) -> 1928 | T28: =SUM(CC28:CF28) -> 1917 | U28: =SUM(CG28:CJ28) -> 1919 | V28: =SUM(CK28:CN28) -> 2007 | W28: =SUM(CO28:CR28) -> 2016 | X28: =SUM(CS28:CV28) -> 2130 | AK28: 402 | AL28: 138 | AM28: 233 | AN28: 190 | AO28: 305 | AP28: 245 | AQ28: 277 | AR28: 328 | AS28: 304 | AT28: 332 | AU28: 380 | AV28: 377 | AW28: 351 | AX28: 375 | AY28: 415 | AZ28: 422 | BA28: 385 | BB28: 437 | BC28: 491 | BD28: 475 | BE28: 419 | BF28: 476 | BG28: 509 | BH28: 416 | BI28: 389 | BJ28: 403 | BK28: 469 | BL28: 438 | BM28: 391 | BN28: 386 | BO28: 430 | BP28: 390 | BQ28: 394 | BR28: 423 | BS28: 450 | BT28: 434 | BU28: 382 | BV28: 450 | BW28: 498 | BX28: 460 | BY28: 463 | BZ28: 509 | CA28: 502 | CB28: 454 | CC28: 423 | CD28: 466 | CE28: 549 | CF28: 479 | CG28: 491 | CH28: 459 | CI28: 499 | CJ28: 470 | CK28: 495 | CL28: 493 | CM28: 523 | CN28: 496 | CO28: 485 | CP28: 517 | CQ28: 553 | CR28: 461 | CS28: 484 | CT28: 460 | CU28: 812 | CV28: 374 | CW28: 427 | CX28: 427 | CY28: 464 | CZ28: 396 | DA28: 448 | DB28: 430 | DC28: 434 | DD28: 396 | DE28: 401 | DF28: 386 | DG28: 381 | DH28: 338 | DI28: 348 | DJ28: 308 | DK28: 265 | DL28: 249 | DM28: 193 | DN28: 137 | DO28: 127 | DP28: 145 | DQ28: 114 | DR28: 120 | DS28: 119 | DT28: 127 | DU28: 94
A29: =+A28+1 -> 16 | B29: Alimta | C29: LLY | D29: Oncology | G29: =SUM(AK29:GH29) -> 34155.5 | I29: =SUM(AK29:AN29) -> 142.5 | J29: =SUM(AO29:AR29) -> 463.2 | K29: =SUM(AS29:AV29) -> 611.4 | L29: =SUM(AW29:AZ29) -> 854 | M29: =SUM(BA29:BD29) -> 1154.8 | N29: =SUM(BE29:BH29) -> 1706.1 | O29: =SUM(BI29:BL29) -> 2208.5 | P29: =SUM(BM29:BP29) -> 2461.1 | Q29: =SUM(BQ29:BT29) -> 2594.2 | R29: =SUM(BU29:BX29) -> 2702.9 | S29: =SUM(BY29:CB29) -> 2792 | T29: =SUM(CC29:CF29) -> 2493 | U29: =SUM(CG29:CJ29) -> 2283.3 | V29: =SUM(CK29:CN29) -> 2062.5 | AK29: 11.6 | AL29: 17.8 | AM29: 40 | AN29: 73.1 | AO29: 93.9 | AP29: 111.2 | AQ29: 122.3 | AR29: 135.8 | AS29: 130 | AT29: 153 | AU29: 157 | AV29: 171.4 | AW29: 187.8 | AX29: 207.1 | AY29: 215 | AZ29: 244.1 | BA29: 247.2 | BB29: 275 | BC29: 313.9 | BD29: 318.7 | BE29: 335.3 | BF29: 385.3 | BG29: 461.9 | BH29: 523.6 | BI29: 527.4 | BJ29: 551.8 | BK29: 560.3 | BL29: 569 | BM29: 579.9 | BN29: 613.4 | BO29: 629.7 | BP29: 638.1 | BQ29: 606.8 | BR29: 659.5 | BS29: 643.6 | BT29: 684.3 | BU29: 616.8 | BV29: 669.4 | BW29: 690.5 | BX29: 726.2 | BY29: 632 | BZ29: 711.6 | CA29: 723.4 | CB29: 725 | CC29: 573 | CD29: 664.3 | CE29: 628.5 | CF29: 627.2 | CG29: 564.2 | CH29: 607.1 | CI29: 570.4 | CJ29: 541.6 | CK29: 489.9 | CL29: 532.9 | CM29: 514.5 | CN29: 525.2 | CO29: 499.6 | CP29: 555.9 | CQ29: 520.5 | CR29: 556.9 | CS29: 499.2 | CT29: 577.8 | CU29: 508.2 | CV29: 530.7 | CW29: 560.1 | CX29: 539.1 | CY29: 578 | CZ29: 652.7 | DA29: 559 | DB29: 610.6 | DC29: 457 | DD29: 434.9 | DE29: 343.9 | DF29: 227.7 | DG29: 119.4 | DH29: 236.6 | DI29: 58.2
A30: =+A29+1 -> 17 | B30: Cymbalta | C30: LLY | D30: Psychiatry | E30: 2 | G30: =SUM(AK30:GH30) -> 32887.4 | I30: =SUM(AK30:AN30) -> 362 | J30: =SUM(AO30:AR30) -> 954.6 | K30: =SUM(AS30:AV30) -> 1734.4 | L30: =SUM(AW30:AZ30) -> 2401 | M30: =SUM(BA30:BD30) -> 2891.3 | N30: =SUM(BE30:BH30) -> 3291.9 | O30: =SUM(BI30:BL30) -> 3722.1 | P30: =SUM(BM30:BP30) -> 4587.3 | Q30: =SUM(BQ30:BT30) -> 5481.6 | R30: =SUM(BU30:BX30) -> 3138.5 | S30: =SUM(BY30:CB30) -> 1296.4 | T30: =SUM(CC30:CF30) -> 901.7 | U30: =SUM(CG30:CJ30) -> 876.5 | V30: =SUM(CK30:CN30) -> 727.5 | AK30: 32.5 | AL30: 61.3 | AM30: 106.8 | AN30: 161.4 | AO30: 182.8 | AP30: 228.8 | AQ30: 233 | AR30: 310 | AS30: 349 | AT30: 424.1 | AU30: 441.8 | AV30: 519.5 | AW30: 513.2 | AX30: 628.3 | AY30: 605.1 | AZ30: 654.4 | BA30: 716.4 | BB30: 721.2 | BC30: 709.3 | BD30: 744.4 | BE30: 790.2 | BF30: 830.8 | BG30: 803.2 | BH30: 867.7 | BI30: 825.3 | BJ30: 984.6 | BK30: 908.8 | BL30: 1003.4 | BM30: 1068.6 | BN30: 1180.7 | BO30: 1114.9 | BP30: 1223.1 | BQ30: 1235.8 | BR30: 1420.4 | BS30: 1328.2 | BT30: 1497.2 | BU30: 1375.8 | BV30: 883.2 | BW30: 478.2 | BX30: 401.3 | BY30: 368 | BZ30: 367.3 | CA30: 287 | CB30: 274.1 | CC30: 242.9 | CD30: 223.6 | CE30: 198.7 | CF30: 236.5 | CG30: 313.5 | CH30: 181.8 | CI30: 174.6 | CJ30: 206.6 | CK30: 183.2 | CL30: 192.8 | CM30: 169.6 | CN30: 181.9 | CO30: 172 | CP30: 184.5 | CQ30: 164.1
A31: =+A7+1 -> 20 | B31: Trulicity | C31: LLY | D31: Diabetes | G31: =SUM(AK31:GH31) -> 31498 | I31: =SUM(AK31:AN31) -> 146.5 | J31: =SUM(AO31:AR31) -> 701 | K31: =SUM(AS31:AV31) -> 1717.8 | L31: =SUM(AW31:AZ31) -> 2923.3 | M31: =SUM(BA31:BD31) -> 3844.4 | N31: =SUM(BE31:BH31) -> 4773.9 | O31: =SUM(BI31:BL31) -> 6090.5 | P31: =SUM(BM31:BP31) -> 7387.3 | Q31: =SUM(BQ31:BT31) -> 3913.3 | R31: =SUM(BU31:BX31) -> 0 | S31: =SUM(BY31:CB31) -> 0 | T31: =SUM(CC31:CF31) -> 0 | U31: =SUM(CG31:CJ31) -> 0 | V31: =SUM(CK31:CN31) -> 0 | AK31: 10.2 | AL31: 18.3 | AM31: 44.3 | AN31: 73.7 | AO31: 112.5 | AP31: 143.6 | AQ31: 201.3 | AR31: 243.6 | AS31: 337 | AT31: 372.9 | AU31: 480.2 | AV31: 527.7 | AW31: 649 | AX31: 678.3 | AY31: 779.8 | AZ31: 816.2 | BA31: 924.7 | BB31: 879.7 | BC31: 1028.5 | BD31: 1011.5 | BE31: 1208.1 | BF31: 1229.4 | BG31: 1229.8 | BH31: 1106.6 | BI31: 1502.4 | BJ31: 1452.4 | BK31: 1535.6 | BL31: 1600.1 | BM31: 1883.7 | BN31: 1741.3 | BO31: 1911.9 | BP31: 1850.4 | BQ31: 1936.2 | BR31: 1977.1
A32: =+A5+1 -> 6 | B32: Prevnar | C32: PFE | D32: Vaccine | G32: =SUM(I32:BN32) -> 82695.365 | I32: 460.6 | J32: 798.2 | K32: 647.5 | L32: 945.6 | M32: 1053.6 | N32: 1508.3 | O32: 1961.3 | P32: 2,439 | Q32: 2,716 | R32: 1825.265 | S32: 3669 | T32: 4145 | U32: 4117 | V32: 3974 | W32: 4464 | X32: 6247 | Y32: 5719 | Z32: 5601 | AA32: 5802 | AB32: 5847 | AC32: 5850 | AD32: 5274 | AE32: 6337 | AF32: 6449
A33: =+A20+1 -> 22 | B33: Cialis | C33: LLY | D33: Cardiovascular | E33: 2 | G33: =SUM(AK33:GH33) -> 28918.5 | I33: =SUM(AK33:AN33) -> 203.3 | J33: =SUM(AO33:AR33) -> 540.1 | K33: =SUM(AS33:AV33) -> 690.4 | L33: =SUM(AW33:AZ33) -> 943.3 | M33: =SUM(BA33:BD33) -> 1216.3 | N33: =SUM(BE33:BH33) -> 1444.5 | O33: =SUM(BI33:BL33) -> 1559.1 | P33: =SUM(BM33:BP33) -> 1699.4 | Q33: =SUM(BQ33:BT33) -> 1875.6 | R33: =SUM(BU33:BX33) -> 1926.8 | S33: =SUM(BY33:CB33) -> 2159.4 | T33: =SUM(CC33:CF33) -> 2291 | U33: =SUM(CG33:CJ33) -> 2310.7 | V33: =SUM(CK33:CN33) -> 2471.7 | AK33: 21.5 | AL33: 37.5 | AM33: 50.2 | AN33: 94.1 | AO33: 108.3 | AP33: 125 | AQ33: 154.1 | AR33: 152.7 | AS33: 150.1 | AT33: 165.1 | AU33: 180.1 | AV33: 195.1 | AW33: 210.1 | AX33: 225.1 | AY33: 240.1 | AZ33: 268 | BA33: 266 | BB33: 293.1 | BC33: 311 | BD33: 346.2 | BE33: 336.9 | BF33: 362.2 | BG33: 376.6 | BH33: 368.8 | BI33: 358.8 | BJ33: 363.6 | BK33: 397.2 | BL33: 439.5 | BM33: 408.3 | BN33: 418.7 | BO33: 406.5 | BP33: 465.9 | BQ33: 434.4 | BR33: 477.2 | BS33: 469.8 | BT33: 494.2 | BU33: 461.8 | BV33: 469.5 | BW33: 482.1 | BX33: 513.4 | BY33: 515 | BZ33: 529.4 | CA33: 526.7 | CB33: 588.3 | CC33: 532.4 | CD33: 567.8 | CE33: 568.4 | CF33: 622.4 | CG33: 538.3 | CH33: 567.9 | CI33: 566.1 | CJ33: 638.4 | CK33: 576.7 | CL33: 630.5 | CM33: 588.2 | CN33: 676.3 | CO33: 533.6 | CP33: 627.3 | CQ33: 564.9 | CR33: 597.4 | CS33: 495.4 | CT33: 538.7 | CU33: 467.1 | CV33: 350.7 | CW33: 308.2 | CX33: 200.2 | CY33: 184.3 | CZ33: 197.8 | DA33: 193 | DB33: 130.7 | DC33: 162.5 | DD33: 120.9 | DE33: 126.8 | DF33: 281 | DG33: 130.9 | DH33: 179.7 | DI33: 217.7 | DJ33: 147 | DK33: 115.7 | DL33: 106.9 | DM33: 100.3 | DN33: 115.6 | DO33: 86.8 | DP33: 78.8 | DQ33: 139.3 | DR33: 87.7
A34: =+A22+1 -> 25 | B34: Entresto | C34: NVS | D34: Cardiovascular | E34: 1 | G34: =SUM(AK34:GH34) -> 23953 | I34: =SUM(AK34:AN34) -> 70 | J34: =SUM(AO34:AR34) -> 315 | K34: =SUM(AS34:AV34) -> 752 | L34: =SUM(AW34:AZ34) -> 1367 | M34: =SUM(BA34:BD34) -> 2097 | N34: =SUM(BE34:BH34) -> 3023 | O34: =SUM(BI34:BL34) -> 4091 | P34: =SUM(BM34:BP34) -> 5341 | Q34: =SUM(BQ34:BT34) -> 6897 | R34: =SUM(BU34:BX34) -> 0 | S34: =SUM(BY34:CB34) -> 0 | T34: =SUM(CC34:CF34) -> 0 | U34: =SUM(CG34:CJ34) -> 0 | V34: =SUM(CK34:CN34) -> 0 | AK34: 16 | AL34: 5 | AM34: 17 | AN34: 32 | AO34: 53 | AP34: 68 | AQ34: 84 | AR34: 110 | AS34: 128 | AT34: 185 | AU34: 200 | AV34: 239 | AW34: 271 | AX34: 318 | AY34: 357 | AZ34: 421 | BA34: 430 | BB34: 518 | BC34: 569 | BD34: 580 | BE34: 632 | BF34: 716 | BG34: 789 | BH34: 886 | BI34: 924 | BJ34: 949 | BK34: 1093 | BL34: 1125 | BM34: 1135 | BN34: 1291 | BO34: 1399 | BP34: 1516 | BQ34: 1485 | BR34: 1635 | BS34: 1879 | BT34: 1898
A35: =+A34+1 -> 26 | B35: Paxlovid | C35: PFE | D35: COVID-19 | E35: 1 | G35: =SUM(AK35:GH35) -> 22574 | I35: =SUM(AK35:AN35) -> 17175 | J35: =SUM(AO35:AR35) -> 6248 | K35: =SUM(AS35:AV35) -> -849 | L35: =SUM(AW35:AZ35) -> 0 | M35: =SUM(BA35:BD35) -> 0 | N35: =SUM(BE35:BH35) -> 0 | O35: =SUM(BI35:BL35) -> 0 | P35: =SUM(BM35:BP35) -> 0 | Q35: =SUM(BQ35:BT35) -> 0 | R35: =SUM(BU35:BX35) -> 0 | S35: =SUM(BY35:CB35) -> 0 | T35: =SUM(CC35:CF35) -> 0 | U35: =SUM(CG35:CJ35) -> 0 | V35: =SUM(CK35:CN35) -> 0 | AK35: 76 | AL35: 1470 | AM35: 8115 | AN35: 7514 | AO35: 1834 | AP35: 4069 | AQ35: 143 | AR35: 202 | AS35: -3135 | AT35: 2035 | AU35: 251
